Workbook

Sheet Summary
B2: [QA] 결과 보고서 | F2: QA 서버 | G2: TD | H2: 최종결과 | I2: 진행중 | L2: * 최종마무리 시 업데이트하여 관리
B4: [QA 정보]
B5: 구분 | D5: 내용
B6: 요청서 | D6: 경기관제 리뉴얼 (골프장 어드민)
B7: 기획서 | D7: 경기관제(클럽어드민) 개선
B8: 계획서 | D8: [QA계획] 경기관제 리뉴얼 (골프장 어드민)
B9: 종료보고서 | D9: [QA결과] 경기관제 리뉴얼 (골프장 어드민)
B10: 수행 일정
B11: 특이사항
B13: [테스트 수행 수] | H13: defect Link 바로가기
B14: 테스트 일자 | C14: 12 | D14: 진행일 | E14: 4 | F14: 예상진척률 | G14: =(($C$31/$C$14)*$E$14)/$C$31 -> 0.33333333 | H14: Fail Rate | I14: =IFERROR(((G45+I45)/D45),0) -> 0
B15: 테스트 환경 | D15: TD # | F15: 진행률 | G15: =($D31-$H31)/($C31-$H31) -> 0.54656489 | H15: PASS Rate | I15: =IFERROR(F31/(C31-H31-E31),0) -> 0.96368715
B16: 구분 | C16: 테스트 전체 수 | D16: 테스트 수행 수 | E16: 잔여 수행 수 | F16: 수행결과
F17: PASS | G17: FAIL | H17: N/A | I17: N/T
B18: Home | C18: =COUNT(INDIRECT("'" & B18 & "'!$A$3:$A")) -> 12 | D18: =sum(F18:H18) -> 12 | E18: =C18-D18 -> 0 | F18: =COUNTIF(INDIRECT("'" & $B18 & "'!$K:$K"), F$17) -> 11 | G18: =COUNTIF(INDIRECT("'" & $B18 & "'!$K:$K"), G$17) -> 1 | H18: =COUNTIF(INDIRECT("'" & $B18 & "'!$K:$K"), H$17) -> 0 | I18: =COUNTIF(INDIRECT("'" & $B18 & "'!$K:$K"), I$17) -> 0
B19: 라운드 관리 | C19: =COUNT(INDIRECT("'" & B19 & "'!$A$3:$A")) -> 304 | D19: =sum(F19:H19) -> 132 | E19: =C19-D19 -> 172 | F19: =COUNTIF(INDIRECT("'" & $B19 & "'!$K:$K"), F$17) -> 115 | G19: =COUNTIF(INDIRECT("'" & $B19 & "'!$K:$K"), G$17) -> 16 | H19: =COUNTIF(INDIRECT("'" & $B19 & "'!$K:$K"), H$17) -> 1 | I19: =COUNTIF(INDIRECT("'" & $B19 & "'!$K:$K"), I$17) -> 12
B20: 관제 관리 | C20: =COUNT(INDIRECT("'" & B20 & "'!$A$3:$A")) -> 58 | D20: =sum(F20:H20) -> 49 | E20: =C20-D20 -> 9 | F20: =COUNTIF(INDIRECT("'" & $B20 & "'!$K:$K"), F$17) -> 41 | G20: =COUNTIF(INDIRECT("'" & $B20 & "'!$K:$K"), G$17) -> 1 | H20: =COUNTIF(INDIRECT("'" & $B20 & "'!$K:$K"), H$17) -> 7 | I20: =COUNTIF(INDIRECT("'" & $B20 & "'!$K:$K"), I$17) -> 0
B21: 태블릿 운영 관리 | C21: =COUNT(INDIRECT("'" & B21 & "'!$A$3:$A")) -> 285 | D21: =sum(F21:H21) -> 285 | E21: =C21-D21 -> 0 | F21: =COUNTIF(INDIRECT("'" & $B21 & "'!$K:$K"), F$17) -> 260 | G21: =COUNTIF(INDIRECT("'" & $B21 & "'!$K:$K"), G$17) -> 9 | H21: =COUNTIF(INDIRECT("'" & $B21 & "'!$K:$K"), H$17) -> 16 | I21: =COUNTIF(INDIRECT("'" & $B21 & "'!$K:$K"), I$17) -> 0
B22: 홀맵 관리 | C22: =COUNT(INDIRECT("'" & B22 & "'!$A$3:$A")) -> 183 | D22: =sum(F22:H22) -> 183 | E22: =C22-D22 -> 0 | F22: =COUNTIF(INDIRECT("'" & $B22 & "'!$K:$K"), F$17) -> 181 | G22: =COUNTIF(INDIRECT("'" & $B22 & "'!$K:$K"), G$17) -> 2 | H22: =COUNTIF(INDIRECT("'" & $B22 & "'!$K:$K"), H$17) -> 0 | I22: =COUNTIF(INDIRECT("'" & $B22 & "'!$K:$K"), I$17) -> 0
B23: 코스 운영 관리 | C23: =COUNT(INDIRECT("'" & B23 & "'!$A$3:$A")) -> 169 | D23: =sum(F23:H23) -> 72 | E23: =C23-D23 -> 97 | F23: =COUNTIF(INDIRECT("'" & $B23 & "'!$K:$K"), F$17) -> 70 | G23: =COUNTIF(INDIRECT("'" & $B23 & "'!$K:$K"), G$17) -> 2 | H23: =COUNTIF(INDIRECT("'" & $B23 & "'!$K:$K"), H$17) -> 0 | I23: =COUNTIF(INDIRECT("'" & $B23 & "'!$K:$K"), I$17) -> 1
B24: 경기 진행 관리 | C24: =COUNT(INDIRECT("'" & B24 & "'!$A$3:$A")) -> 178 | D24: =sum(F24:H24) -> 0 | E24: =C24-D24 -> 178 | F24: =COUNTIF(INDIRECT("'" & $B24 & "'!$K:$K"), F$17) -> 0 | G24: =COUNTIF(INDIRECT("'" & $B24 & "'!$K:$K"), G$17) -> 0 | H24: =COUNTIF(INDIRECT("'" & $B24 & "'!$K:$K"), H$17) -> 0 | I24: =COUNTIF(INDIRECT("'" & $B24 & "'!$K:$K"), I$17) -> 0
B25: 캐디 관리 | C25: =COUNT(INDIRECT("'" & B25 & "'!$A$3:$A")) -> 89 | D25: =sum(F25:H25) -> 85 | E25: =C25-D25 -> 4 | F25: =COUNTIF(INDIRECT("'" & $B25 & "'!$K:$K"), F$17) -> 83 | G25: =COUNTIF(INDIRECT("'" & $B25 & "'!$K:$K"), G$17) -> 1 | H25: =COUNTIF(INDIRECT("'" & $B25 & "'!$K:$K"), H$17) -> 1 | I25: =COUNTIF(INDIRECT("'" & $B25 & "'!$K:$K"), I$17) -> 0
B26: 캐디피 관리 | C26: =COUNT(INDIRECT("'" & B26 & "'!$A$3:$A")) -> 246 | D26: =sum(F26:H26) -> 11 | E26: =C26-D26 -> 235 | F26: =COUNTIF(INDIRECT("'" & $B26 & "'!$K:$K"), F$17) -> 10 | G26: =COUNTIF(INDIRECT("'" & $B26 & "'!$K:$K"), G$17) -> 1 | H26: =COUNTIF(INDIRECT("'" & $B26 & "'!$K:$K"), H$17) -> 0 | I26: =COUNTIF(INDIRECT("'" & $B26 & "'!$K:$K"), I$17) -> 0
B27: 배토 관리 | C27: =COUNT(INDIRECT("'" & B27 & "'!$A$3:$A")) -> 57 | D27: =sum(F27:H27) -> 20 | E27: =C27-D27 -> 37 | F27: =COUNTIF(INDIRECT("'" & $B27 & "'!$K:$K"), F$17) -> 20 | G27: =COUNTIF(INDIRECT("'" & $B27 & "'!$K:$K"), G$17) -> 0 | H27: =COUNTIF(INDIRECT("'" & $B27 & "'!$K:$K"), H$17) -> 0 | I27: =COUNTIF(INDIRECT("'" & $B27 & "'!$K:$K"), I$17) -> 0
B28: 식음 관리 | C28: =COUNT(INDIRECT("'" & B28 & "'!$A$3:$A")) -> 230 | D28: =sum(F28:H28) -> 71 | E28: =C28-D28 -> 159 | F28: =COUNTIF(INDIRECT("'" & $B28 & "'!$K:$K"), F$17) -> 67 | G28: =COUNTIF(INDIRECT("'" & $B28 & "'!$K:$K"), G$17) -> 3 | H28: =COUNTIF(INDIRECT("'" & $B28 & "'!$K:$K"), H$17) -> 1 | I28: =COUNTIF(INDIRECT("'" & $B28 & "'!$K:$K"), I$17) -> 1
B29: 고객 평가 관리 | C29: =COUNT(INDIRECT("'" & B29 & "'!$A$3:$A")) -> 114 | D29: =sum(F29:H29) -> 114 | E29: =C29-D29 -> 0 | F29: =COUNTIF(INDIRECT("'" & $B29 & "'!$K:$K"), F$17) -> 112 | G29: =COUNTIF(INDIRECT("'" & $B29 & "'!$K:$K"), G$17) -> 2 | H29: =COUNTIF(INDIRECT("'" & $B29 & "'!$K:$K"), H$17) -> 0 | I29: =COUNTIF(INDIRECT("'" & $B29 & "'!$K:$K"), I$17) -> 0
B30: 계정 관리 | C30: =COUNT(INDIRECT("'" & B30 & "'!$A$3:$A")) -> 66 | D30: =sum(F30:H30) -> 66 | E30: =C30-D30 -> 0 | F30: =COUNTIF(INDIRECT("'" & $B30 & "'!$K:$K"), F$17) -> 65 | G30: =COUNTIF(INDIRECT("'" & $B30 & "'!$K:$K"), G$17) -> 1 | H30: =COUNTIF(INDIRECT("'" & $B30 & "'!$K:$K"), H$17) -> 0 | I30: =COUNTIF(INDIRECT("'" & $B30 & "'!$K:$K"), I$17) -> 0
B31: Total | C31: =sum(C18:C30) -> 1991 | D31: =sum(D18:D30) -> 1100 | E31: =C31-D31 -> 891 | F31: =sum(F18:F30) -> 1035 | G31: =sum(G18:G30) -> 39 | H31: =sum(H18:H30) -> 26 | I31: =sum(I18:I30) -> 14
B34: [이슈 처리 현황]
B35: 이슈 발생율 | C35: 이슈 처리율 | D35: Total 발생 버그
D36: Total | E36: 즉시 | F36: 긴급 | G36: 높음 | H36: 보통 | I36: 낮음
C37: =IFERROR(D39/D37,0) -> 0.69318182 | D37: =sum(E37:I37) -> 88 | E37: =E39+E38 -> 0 | F37: =F39+F38 -> 0 | G37: =G39+G38 -> 13 | H37: =H39+H38 -> 68 | I37: =I39+I38 -> 7
B38: 잔여 이슈 | D38: =sum(E38:I38) -> 27 | E38: =countifs('이슈리스트'!$C$2:$C991,E$36,'이슈리스트'!$J$2:$J991,"해야 할 일")+countifs('이슈리스트'!$C$2:$C991,E$36,'이슈리스트'!$J$2:$J991,"진행 중") -> 0 | F38: =countifs('이슈리스트'!$C$2:$C991,F$36,'이슈리스트'!$J$2:$J991,"해야 할 일")+countifs('이슈리스트'!$C$2:$C991,F$36,'이슈리스트'!$J$2:$J991,"진행 중") -> 0 | G38: =countifs('이슈리스트'!$C$2:$C991,G$36,'이슈리스트'!$J$2:$J991,"해야 할 일")+countifs('이슈리스트'!$C$2:$C991,G$36,'이슈리스트'!$J$2:$J991,"진행 중") -> 3 | H38: =countifs('이슈리스트'!$C$2:$C991,H$36,'이슈리스트'!$J$2:$J991,"해야 할 일")+countifs('이슈리스트'!$C$2:$C991,H$36,'이슈리스트'!$J$2:$J991,"진행 중") -> 21 | I38: =countifs('이슈리스트'!$C$2:$C991,I$36,'이슈리스트'!$J$2:$J991,"해야 할 일")+countifs('이슈리스트'!$C$2:$C991,I$36,'이슈리스트'!$J$2:$J991,"진행 중") -> 3 | K38: 할 일 | L38: 진행 중
B39: 완료 이슈 | D39: =sum(E39:I39) -> 61 | E39: =countifs('이슈리스트'!$C$2:$C991,E$36,'이슈리스트'!$J$2:$J991,$K$39) -> 0 | F39: =countifs('이슈리스트'!$C$2:$C991,F$36,'이슈리스트'!$J$2:$J991,$K$39) -> 0 | G39: =countifs('이슈리스트'!$C$2:$C991,G$36,'이슈리스트'!$J$2:$J991,$K$39) -> 10 | H39: =countifs('이슈리스트'!$C$2:$C991,H$36,'이슈리스트'!$J$2:$J991,$K$39) -> 47 | I39: =countifs('이슈리스트'!$C$2:$C991,I$36,'이슈리스트'!$J$2:$J991,$K$39) -> 4 | K39: 완료
C40: 중요도별 % | E40: =E37/$E$39 -> #DIV/0! | F40: =F37/$E$39 -> #DIV/0! | G40: =G37/$E$39 -> #DIV/0! | H40: =H37/$E$39 -> #DIV/0! | I40: =I37/$E$39 -> #DIV/0!
B46: * 필요에 따라 이력누적이 필요한경우 자유롭게 아래 영역에 추가하여 사용.

Sheet IA
A1: No. | B1: 화면 (진입점 구분) | E1: 담당자 (TC) | F1: 완료여부 (TC) | G1: 담당자 (QA) | H1: 완료여부 (QA) | I1: 비고
B2: 0 depth | C2: 1 depth | D2: 2 depth | K2: No. | L2: 기존 0depth | M2: 기존 1depth | N2: 0depth (변경) | O2: 1depth (변경) | P2: 기대결과 | Q2: 확인 결과 | S2: 대메뉴(0depth) | T2: 메뉴(1depth) | U2: 구현여부 | V2: URL | W2: 비고 | X2: 현상 | Y2: 기대 결과(문구 변경) | Z2: 분석여부 | AA2: 스크립트 작성
A3: =COUNTA($C$3:C3) -> 1 | B3: 홈 | C3: - | E3: 한지연 | F3: 완료 | G3: 한지연 | K3: 1 | L3: HOME | M3: - | N3: 홈 | O3: - | P3: ✎ 변경 메뉴명 변경: HOME → 홈 | S3: 홈 | U3: 구현 | V3: https://td17.smartscore.kr/club/page/home | W3: 대메뉴 존재
A4: =COUNTA($C$3:C4) -> 2 | B4: 라운드관리 | C4: 내장 현황 | E4: 한지연 | F4: 완료 | G4: 한지연 | K4: 2 | L4: 라운드관리 | M4: (없음-기존 홈 화면 항목) | N4: 라운드관리 | O4: 내장 현황 | P4: ✚ 추가 신규 생성 / 기존 홈화면 항목 편입 | S4: 라운드관리 | T4: 내장 현황 | U4: 구현 | V4: https://td17.smartscore.kr/club/page/round-visit?cp=1 | W4: 진입 성공
A5: =COUNTA($C$3:C5) -> 3 | C5: 내장 통계 | E5: 한지연 | F5: 완료 | G5: 한지연 | K5: 3 | L5: 라운드관리 | M5: 내장 통계 | N5: 라운드관리 | O5: 내장 통계 | P5: ● 유지 유지 (메뉴명 동일) | S5: 라운드관리 | T5: 내장 통계 | U5: 구현 | V5: https://td17.smartscore.kr/club/page/round-visit-statistics?cp=1&searchStartDate=2026-03-03&searchEndDate=2026-06-01 | W5: 진입 성공
A6: =COUNTA($C$3:C6) -> 4 | C6: 전체 라운드 | E6: 한지연 | F6: 완료 | G6: 한지연 | K6: 4 | L6: 라운드관리 | M6: 전체 라운드 | N6: 라운드관리 | O6: 전체 라운드 | P6: ● 유지 유지 | S6: 라운드관리 | T6: 전체 라운드 | U6: 구현 | V6: https://td17.smartscore.kr/club/page/round-all | W6: 진입 성공 | X6: 전체라운드 | Y6: 전체 라운드
A7: =COUNTA($C$3:C7) -> 5 | C7: 단체 라운드 | I7: 범위제외 | K7: 5 | L7: 라운드관리 | M7: 단체 라운드 | N7: 라운드관리 | O7: 단체 라운드 | P7: ● 유지 유지 | S7: 라운드관리 | T7: 단체 라운드 | U7: 구현 | V7: https://td17.smartscore.kr/club/page/round-group | W7: 진입 성공 | X7: 단체라운드 | Y7: 단체 라운드
A8: =COUNTA($C$3:C8) -> 6 | C8: 라운드 설정 | E8: 한지연 | F8: 완료 | G8: 한지연 | K8: 6 | L8: 라운드관리 | M8: 라운드 코스관리 | N8: 라운드관리 | O8: 라운드 설정 | P8: ✎ 변경 메뉴명 변경: 라운드 코스관리 → 라운드 설정 | S8: 라운드관리 | T8: 라운드 설정 | U8: 구현 | V8: https://td17.smartscore.kr/club/page/round-course | W8: 진입 성공
A9: =COUNTA($C$3:C9) -> 7 | C9: 카트 관리 | E9: 한지연 | F9: 완료 | G9: 한지연 | K9: 7 | L9: 라이브관리 | M9: (없음) | N9: 라운드관리 | O9: 카트 관리 | P9: → 이동 기존 라이브관리 > 카트관리에서 이동 / 라운드관리로 편입 | S9: 라운드관리 | T9: 카트 관리 | U9: 구현 | V9: https://td17.smartscore.kr/club/page/cart-all | W9: 진입 성공 | X9: 카트관리 | Y9: 카트 관리
A10: =COUNTA($C$3:C10) -> 8 | C10: 홀별 정산 관리 | E10: 한지연 | F10: 진행중 | G10: 한지연 | K10: 8 | L10: 라이브관리 | M10: 홀별정산관리 | N10: 라운드관리 | O10: 홀별 정산 관리 | P10: → 이동 기존 라이브관리에서 라운드관리로 이동 | S10: 라운드관리 | T10: 홀별 정산 관리 | U10: 구현 | V10: https://td17.smartscore.kr/club/page/live-hole-calc | W10: 진입 성공 | X10: 홀별정산관리 | Y10: 홀별 정산 관리
A11: =COUNTA($C$3:C11) -> 9 | B11: 관제 관리 | C11: 관제팝업 | I11: 범위제외 | K11: 9 | L11: 관제관리 | M11: 관제팝업 | N11: 관제 관리 | O11: 관제팝업 | P11: ● 유지 유지 (0depth 띄어쓰기 추가) | S11: 관제 관리 | T11: 관제 팝업 | U11: 구현 | V11: https://td17.smartscore.kr/club/page/live-hole-calc | W11: 진입(URL 동일) | X11: 관제팝업 | Y11: 관제 팝업
A12: =COUNTA($C$3:C12) -> 10 | C12: 메시지 기록 조회 | E12: 박경선 | F12: 완료 | G12: 박경선 | K12: 10 | L12: 관제관리 | M12: 메시지 기록 조회 | N12: 관제 관리 | O12: 메시지 기록 조회 | P12: ✎ 변경 메뉴명 변경: 메시지 기록 조회 → 메시지 기기 조회 | S12: 관제 관리 | T12: 메시지 기록 조회 | U12: 미구현 | W12: SNB 메뉴 없음/명칭 불일치 | X12: PASS
A13: =COUNTA($C$3:C13) -> 11 | C13: 라이브채팅 공지 조회 | E13: 박경선 | F13: 완료 | G13: 박경선 | K13: 11 | L13: 관제관리 | M13: 라이브채팅 공지 조회 | N13: 관제 관리 | O13: 라이브채팅 공지 조회 | P13: ● 유지 유지 | S13: 관제 관리 | T13: 라이브채팅 공지 조회 | U13: 구현 | V13: https://td17.smartscore.kr/club/page/control-live-chat | W13: 진입 성공
A14: =COUNTA($C$3:C14) -> 12 | C14: 아이콘 관리 | E14: 박경선 | F14: 완료 | G14: 박경선 | K14: 12 | L14: 관제관리 | M14: 아이콘 관리 (라이브관리에도 존재) | N14: 관제 관리 | O14: 아이콘 관리 | P14: → 이동 기존 라이브관리 > 아이콘 관리와 통합·이동 | S14: 관제 관리 | T14: 아이콘 관리 | U14: 구현 | V14: https://td17.smartscore.kr/club/page/live-icon | W14: 진입 성공
A15: =COUNTA($C$3:C15) -> 13 | C15: 카트이동경로 확인 | E15: 박경선 | F15: - | G15: 박경선 | I15: 없음 | K15: 13 | L15: 관제관리 | M15: (없음) | N15: 관제 관리 | O15: 카트이동경로 확인 | P15: ✚ 추가 신규 추가 메뉴 | S15: 관제 관리 | T15: 카트이동경로 확인 | U15: 구현 | V15: https://td17.smartscore.kr/club/page/live-cart-trace | W15: 진입 성공
A16: =COUNTA($C$3:C16) -> 14 | B16: 태블릿 운영 관리 | C16: 태블릿 기능 설정 | E16: 박경선 | F16: 완료 | G16: 박경선 | K16: 14 | L16: 라이브관리 | M16: 경기진행관리 | N16: 태블릿 운영 관리 | O16: 태블릿 기능 설정 | P16: → 이동 신규 생성 대메뉴 / 기존 라이브관리 > 경기진행관리에서 이동 | S16: 태블릿 운영 관리 | T16: 태블릿 기능 설정 | U16: 구현 | V16: https://td17.smartscore.kr/club/page/live-game | W16: 진입 성공
A17: =COUNTA($C$3:C17) -> 15 | C17: 메시지 관리 | E17: 박경선 | F17: 완료 | G17: 박경선 | K17: 15 | L17: 라이브관리 | M17: 메시지관리 | N17: 태블릿 운영 관리 | O17: 메시지 관리 | P17: → 이동 기존 라이브관리에서 이동 | S17: 태블릿 운영 관리 | T17: 메시지 관리 | U17: 구현 | V17: https://td17.smartscore.kr/club/page/live-message | W17: 진입 성공
A18: =COUNTA($C$3:C18) -> 16 | C18: 홀 이벤트 관리 | E18: 박경선 | F18: 완료 | G18: 박경선 | K18: 16 | L18: 라이브관리 | M18: 홀이벤트관리 | N18: 태블릿 운영 관리 | O18: 홀 이벤트 관리 | P18: → 이동 기존 라이브관리에서 이동 / 메뉴명 변경: 홀이벤트관리 → 홀 이벤트 관리 | S18: 태블릿 운영 관리 | T18: 홀 이벤트 관리 | U18: 구현 | V18: https://td17.smartscore.kr/club/page/live-hole-event | W18: 진입 성공
A19: =COUNTA($C$3:C19) -> 17 | B19: 홀맵 관리 | C19: 홀맵 구역 설정 | E19: 전영신 | F19: 완료 | G19: 전영신 | K19: 17 | L19: 관제관리 | M19: 홀맵 구역 관리 | N19: 홀맵 관리 | O19: 홀맵 구역 설정 | P19: → 이동 신규 생성 대메뉴 / 기존 관제관리 > 홀맵 구역 관리에서 분리 이동 | S19: 홀맵 관리 | T19: 홀맵 구역 설정 | U19: 미구현 | W19: SNB 메뉴 없음/명칭 불일치 | X19: 홀맵 구역 관리 | Y19: 홀맵 구역 설정
A20: =COUNTA($C$3:C20) -> 18 | C20: 카트패스 진입여부 설정 | E20: 전영신 | F20: 완료 | G20: 전영신 | K20: 18 | L20: (없음) | M20: (없음) | N20: 홀맵 관리 | O20: 카트패스 진입여부 설정 | P20: ✚ 추가 신규 추가 메뉴 | S20: 홀맵 관리 | T20: 카트패스 진입여부 설정 | U20: 구현 | V20: https://td17.smartscore.kr/club/page/holemap-cart-entrance | W20: 진입 성공
A21: =COUNTA($C$3:C21) -> 19 | C21: 티샷 유의 거리 설정 | E21: 전영신 | F21: 완료 | G21: 전영신 | K21: 19 | L21: (없음) | M21: (없음) | N21: 홀맵 관리 | O21: 티샷 유의 거리 설정 | P21: ✚ 추가 신규 추가 메뉴 | S21: 홀맵 관리 | T21: 티샷 유의 거리 설정 | U21: 구현 | V21: https://td17.smartscore.kr/club/page/holemap-teeshot-distance | W21: 진입 성공
A22: =COUNTA($C$3:C22) -> 20 | C22: 홀맵 미리보기 | E22: 전영신 | F22: 진행중 | G22: 전영신 | K22: 20 | L22: (없음) | M22: (없음) | N22: 홀맵 관리 | O22: 홀맵 미리보기 | P22: ✚ 추가 신규 추가 메뉴 | S22: 홀맵 관리 | T22: 홀맵 미리보기 | U22: 구현 | V22: https://td17.smartscore.kr/club/page/holemap-preview | W22: 진입 성공
A23: =COUNTA($C$3:C23) -> 21 | B23: 코스 운영 관리 | C23: 핀 포지션 관리 | E23: 전영신 | F23: 완료 | G23: 전영신 | K23: 21 | L23: 관제관리 | M23: 핀포지션관리 | N23: 코스 운영 관리 | O23: 핀 포지션 관리 | P23: → 이동 기존 관제관리에서 이동 / 메뉴명 변경 | S23: 코스 운영 관리 | T23: 핀 포지션 관리 | U23: 구현 | V23: https://td17.smartscore.kr/club/page/course-analysis-pin-position | W23: 진입 성공
A24: =COUNTA($C$3:C24) -> 22 | C24: 핀 포지션 변경이력 | E24: 전영신 | F24: 완료 | G24: 전영신 | K24: 22 | L24: 코스분석 | M24: 핀포지션 변경이력 | N24: 코스 운영 관리 | O24: 핀 포지션 변경이력 | P24: → 이동 기존 코스분석에서 이동 / 메뉴명 변경 | S24: 코스 운영 관리 | T24: 핀 포지션 변경이력 | U24: 구현 | V24: https://td17.smartscore.kr/club/page/course-analysis-pin-history | W24: 진입 성공
A25: =COUNTA($C$3:C25) -> 23 | C25: 핀 포지션 분석 | E25: 전영신 | F25: 완료 | G25: 전영신 | K25: 23 | L25: 코스분석 | M25: 핀포지션분석 | N25: 코스 운영 관리 | O25: 핀 포지션 분석 | P25: → 이동 기존 코스분석에서 이동 / 메뉴명 변경 | S25: 코스 운영 관리 | T25: 핀 포지션 분석 | U25: 구현 | V25: https://td17.smartscore.kr/club/page/course-analysis-pin | W25: 진입 성공
A26: =COUNTA($C$3:C26) -> 24 | C26: 코스 분석 | E26: 전영신 | F26: 완료 | G26: 전영신 | K26: 24 | L26: 코스분석 | M26: 코스분석 | N26: 코스 운영 관리 | O26: 코스 분석 | P26: → 이동 기존 코스분석에서 이동 | S26: 코스 운영 관리 | T26: 코스 분석 | U26: 구현 | V26: https://td17.smartscore.kr/club/page/course-analysis-detail | W26: 진입 성공
A27: =COUNTA($C$3:C27) -> 25 | C27: 그린 스피드 | E27: 전영신 | F27: 완료 | G27: 전영신 | K27: 25 | L27: 웰컴 메시지 | M27: 그린스피드 | N27: 코스 운영 관리 | O27: 그린 스피드 | P27: → 이동 기존 웰컴 메시지에서 이동 / 메뉴명 변경 | S27: 코스 운영 관리 | T27: 그린 스피드 | U27: 구현 | V27: https://td17.smartscore.kr/club/page/course-analysis-green-speed | W27: 진입 성공
A28: =COUNTA($C$3:C28) -> 26 | C28: 골프장 소식 | E28: 전영신 | F28: 완료 | G28: 전영신 | K28: 26 | L28: 웰컴 메시지 | M28: 골프장소식 | N28: 코스 운영 관리 | O28: 골프장 소식 | P28: → 이동 기존 웰컴 메시지에서 이동 / 메뉴명 변경 | S28: 코스 운영 관리 | T28: 골프장 소식 | U28: 구현 | V28: https://td17.smartscore.kr/club/page/course-analysis-club-news | W28: 진입 성공
A29: =COUNTA($C$3:C29) -> 27 | B29: 경기 진행 관리 | C29: 진행시간 표준 설정 | E29: 전영신 | F29: 완료 | G29: 전영신 | K29: 27 | L29: 관제관리 | M29: 진행시간 표준설정 | N29: 경기 진행 관리 | O29: 진행시간 표준 설정 | P29: → 이동 신규 생성 대메뉴 / 기존 관제관리에서 이동 | S29: 경기 진행 관리 | T29: 진행시간 표준 설정 | U29: 구현 | V29: https://td17.smartscore.kr/club/page/control-time-standard | W29: 진입 성공
A30: =COUNTA($C$3:C30) -> 28 | C30: 진행시간 실시간 | E30: 전영신 | F30: 완료 | G30: 전영신 | K30: 28 | L30: 관제관리 | M30: 진행시간 실시간 | N30: 경기 진행 관리 | O30: 진행시간 실시간 | P30: → 이동 기존 관제관리에서 이동 | S30: 경기 진행 관리 | T30: 진행시간 실시간 | U30: 구현 | V30: https://td17.smartscore.kr/club/page/control-time-realtime | W30: 진입 성공
A31: =COUNTA($C$3:C31) -> 29 | C31: 진행시간 조회 | E31: 전영신 | F31: 완료 | G31: 전영신 | K31: 29 | L31: 관제관리 | M31: 진행시간 조회 | N31: 경기 진행 관리 | O31: 진행시간 조회 | P31: → 이동 기존 관제관리에서 이동 | S31: 경기 진행 관리 | T31: 진행시간 조회 | U31: 구현 | V31: https://td17.smartscore.kr/club/page/control-time-search | W31: 진입 성공
A32: =COUNTA($C$3:C32) -> 30 | C32: 진행시간 통계 | E32: 전영신 | F32: 완료 | G32: 전영신 | K32: 30 | L32: 관제관리 | M32: 진행시간 통계 | N32: 경기 진행 관리 | O32: 진행시간 통계 | P32: → 이동 기존 관제관리에서 이동 | S32: 경기 진행 관리 | T32: 진행시간 통계 | U32: 구현 | V32: https://td17.smartscore.kr/club/page/control-time-statistics | W32: 진입 성공
A33: =COUNTA($C$3:C33) -> 31 | B33: 캐디 관리 | C33: 캐디 리스트 | E33: 박경선 | F33: 완료 | G33: 박경선 | K33: 31 | L33: 캐디관리 | M33: 전체캐디 | N33: 캐디 관리 | O33: 캐디 리스트 | P33: ✎ 변경 메뉴명 변경: 전체캐디 → 캐디 리스트 | S33: 캐디 관리 | T33: 캐디 리스트 | U33: 미구현 | W33: SNB 메뉴 없음/명칭 불일치 | X33: 캐디관리 | Y33: 캐디 관리
A34: =COUNTA($C$3:C34) -> 32 | C34: 캐디 등록 관리 | E34: 박경선 | F34: 완료 | G34: 박경선 | K34: 32 | L34: 캐디관리 | M34: 캐디등록/수정/해지 | N34: 캐디 관리 | O34: 캐디 등록 관리 | P34: ✎ 변경 메뉴명 변경: 캐디등록/수정/해지 → 캐디 등록 관리 | S34: 캐디 관리 | T34: 캐디 등록 관리 | U34: 미구현 | W34: SNB 메뉴 없음/명칭 불일치 | X34: 캐디 등록 | Y34: 캐디 등록 관리
A35: =COUNTA($C$3:C35) -> 33 | C35: 캐디 실적 | E35: 박경선 | F35: 완료 | G35: 박경선 | K35: 33 | L35: 캐디관리 | M35: 캐디실적 | N35: 캐디 관리 | O35: 캐디 실적 | P35: ● 유지 유지 | S35: 캐디 관리 | T35: 캐디 실적 | U35: 구현 | V35: https://td17.smartscore.kr/club/page/caddie-performance | W35: 진입 성공 | X35: 캐디 실적 페이지 | Y35: 캐디 실적
A36: =COUNTA($C$3:C36) -> 34 | B36: 캐디피 관리 | C36: 캐디피 설정 | E36: 박경선 | F36: 완료 | G36: 박경선 | K36: 34 | L36: 캐디피 관리 | M36: 캐디피 설정 | N36: 캐디피 관리 | O36: 캐디피 설정 | P36: ● 유지 유지 (하위메뉴 포함) | S36: 캐디피 관리 | T36: 캐디피 설정 | U36: 미구현 | W36: SNB 대메뉴 없음/명칭 불일치
A37: =COUNTA($C$3:C37) -> 35 | C37: 캐디피 통계 | E37: 박경선 | F37: 완료 | G37: 박경선 | K37: 35 | L37: 캐디피 관리 | M37: 캐디피 통계 | N37: 캐디피 관리 | O37: 캐디피 통계 | P37: ● 유지 유지 | S37: 캐디피 관리 | T37: 캐디피 통계 | U37: 미구현 | W37: SNB 대메뉴 없음/명칭 불일치
A38: =COUNTA($C$3:C38) -> 36 | C38: 캐디피 결제 내역 | E38: 박경선 | F38: 완료 | G38: 박경선 | K38: 36 | L38: 캐디피 관리 | M38: 캐디피 결제내역 | N38: 캐디피 관리 | O38: 캐디피 결제 내역 | P38: ✎ 변경 메뉴명 띄어쓰기 변경 | S38: 캐디피 관리 | T38: 캐디피 결제 내역 | U38: 미구현 | W38: SNB 대메뉴 없음/명칭 불일치
A39: =COUNTA($C$3:C39) -> 37 | C39: 캐디 자료/신고서 | E39: 박경선 | F39: 완료 | G39: 박경선 | K39: 37 | L39: 캐디피 관리 | M39: 캐디 자료 / 신고서 | N39: 캐디피 관리 | O39: 캐디 자료/신고서 | P39: ● 유지 유지 | S39: 캐디피 관리 | T39: 캐디 자료/신고서 | U39: 미구현 | W39: SNB 대메뉴 없음/명칭 불일치
A40: =COUNTA($C$3:C40) -> 38 | B40: 배토 관리 | C40: 배토 기록 조회 | E40: 강나연 | F40: 완료 | G40: 강나연 | K40: 38 | L40: 라운드관리 | M40: 배토기록조회 | N40: 배토 관리 | O40: 배토 기록 조회 | P40: → 이동 신규 생성 대메뉴 / 기존 라운드관리에서 이동 | S40: 배토 관리 | T40: 배토 기록 조회 | U40: 구현 | V40: https://td17.smartscore.kr/club/page/topdressing-record | W40: 진입 성공
...

Sheet Sanity
A1: No. | B1: 화면 | E1: 절차 | F1: 확인사항 및 기대결과 | G1: QA 확인 결과 | H1: Comment | I1: 담당자
B2: 1 depth | C2: 2 depth | D2: 3 depth
A3: =COUNTA($F$3:$F3) -> 1 | B3: 조인 | C3: 홈 | E3: 1. 홈 메뉴 선택 | F3: 1. 홈 메뉴 진입 2. 나의 조인 내역 표시 3. 조인 등록, 조인찾기 버튼 제공 4. 추천 키워드 등록 기능 제공 5. 추천 키워드 리스트 제공
D4: 나의조인 | E4: 1. 홈 메뉴 선택 2. 나의 조인 확인 | F4: 1. 조인 항목 표시 됨
D5: new 뱃지 | E5: 1. 홈 메뉴 선택 2. 나의 조인 > 신청자내역, 대화, 신청정보 확인. | F5: 1. 새로운 정보가 있을 때 n 뱃지 표시
A6: =COUNTA($F$3:$F6) -> 3 | C6: 부부커플 | E6: 1. 부부 커플 메뉴 선택
A7: =COUNTA($F$3:$F7) -> 3 | C7: 남남여여
A8: =COUNTA($F$3:$F8) -> 3 | C8: 스크린
A9: =COUNTA($F$3:$F9) -> 3 | C9: 1박2일
A10: =COUNTA($F$3:$F10) -> 3 | C10: 해외동반
A11: =COUNTA($F$3:$F11) -> 3 | B11: 홈 | C11: 조인등록
C12: 조인 수정
C13: 조인 참여
A14: =COUNTA($F$3:$F14) -> 3 | B14: 홈 | C14: 조인찾기
A15: =COUNTA($F$3:$F15) -> 3 | B15: 홈 | C15: 키워드 등록
A16: =COUNTA($F$3:$F16) -> 3 | C16: 키워드 리스트
A17: =COUNTA($F$3:$F17) -> 3
A18: =COUNTA($F$3:$F18) -> 3
A19: =COUNTA($F$3:$F19) -> 3
A20: =COUNTA($F$3:$F20) -> 3
A21: =COUNTA($F$3:$F21) -> 3
A22: =COUNTA($F$3:$F22) -> 3
A23: =COUNTA($F$3:$F23) -> 3
A24: =COUNTA($F$3:$F24) -> 3

Sheet 시트15
A1: SMARTSCORE 경기관제(클럽어드민) 개선 — Information Architecture
A2: No. | B2: 대메뉴 (Depth 1) | C2: 중메뉴 (Depth 2) | D2: 소메뉴 (Depth 3) | E2: 주요 기능 / 기획 정의 | F2: 기획서 정의 여부 | G2: 비고
A3: 1 | B3: HOME | C3: – | D3: – | E3: 공지사항 팝업(최신 공지 제목 표시, 좌/우 화살표로 이전/다음 전환) 클럽공지 제목 클릭 시 본문 진입 언어 선택(KR/EN) 셀렉트 칩 골프장명 표시 | F3: O | G3: 공통 상단 포함
A4: 2 | B4: 라운드 관리 | C4: 내장 현황 | D4: – | E4: 당일 내장객 현황 조회 내장객 남/여 구분 표시 유효 내장객 수 표시 | F4: O
A5: 3 | C5: 내장 통계 | D5: – | E5: 기간별 내장 통계 조회 내보내기(엑셀 다운로드) 기능 데이터 없음 시 '내역이 없습니다' 표시 | F5: O
A6: 4 | C6: 전체 라운드 | D6: – | E6: 태블릿 전송 라운드 전체 기록 조회(90일 보관) 라운드 상세 정보 관리 사진 팝업(클럽사진 이동/일반사진 이동 알럿) 스코어카드 레이어팝업 라운드 상태 Live 시 수정·이름변경·삭제·코스변경·티오프변경 버튼 미노출 오버타수 변경·총타수 변경 버튼 전환 라운드 날짜·티오프 시간 변경 팝업 코스변경 알럿 ('선택하신 코스로 전,후반 코스를 변경합니다.') 라운드 삭제 알럿 고객 내장객 사진 1일 보관 | F6: O
A7: 5 | C7: 단체 라운드 | D7: – | E7: 별도 프로젝트 [단체팀 고도화] 진행 중 — 설명 생략 | F7: △ | G7: 단체팀 고도화 별도
A8: 6 | C8: 라운드 설정 | D8: – | E8: 라운드 기준 홀 수 설정(6홀/9홀/18홀 선택) 초기화·저장 버튼 홀 난이도 설정(홀별 select박스, 중복 난이도 불가) 롱기스트·니어리스트 기본 적용 홀 설정 신페리오 적용 홀 설정(랜덤선택·초기화·저장) 코스별 롱기/니어 홀 설정 | F8: O | G8: 기존 메뉴 UI 통합
A9: 7 | C9: 카트 관리 | D9: – | E9: 카트 목록 조회(사용구분 필터: 전체/사용/중지, 기본값:사용) 조회일 선택 시 해당일 운행 카트만 표시 카트 등록 레이어팝업(기존 펼치기→팝업 변경) 카트 번호 일괄 생성(최대 4자리, 중복 미생성) 카트 별 라운드 기록 레이어팝업 - 기본 조회기간: 과거 30일 / 전년도 이전 조회 불가 - 순번 내림차순 정렬 | F9: O
A10: 8 | C10: 홀별 정산 관리 | D10: – | E10: 홀별 정산 기능 설정 토글(태블릿 홀정산 요청 활성화) 홀별 정산 사유 관리(최대 3개, 기본값: 약친후/부상/천재지변) 조회일·내장객명·캐디명 기준 홀정산 요청 내역 검색 내역 없음 처리 | F10: O
A11: 9 | B11: 관제 관리 | C11: 관제팝업 | D11: – | E11: 관제 지도 팝업 — 기존 기능 UI 변경 | F11: △ | G11: 상세 미정의
A12: 10 | C12: 메시지 기록 조회 | D12: – | E12: 기존 기능 유지 / UI만 데이터마케팅 기준으로 변경 문구 수정 | F12: O | G12: Maintain
A13: 11 | C13: 라이브채팅 공지 조회 | D13: – | E13: 라이브채팅 공지사항 기록 조회 1개월 이내 공지사항만 보관 | F13: O
A14: 12 | C14: 아이콘 관리 | D14: – | E14: 아이콘 시인성 향상 사용유무 설정(저장 Btn) 아이콘관리 사용유무 설정 코스별 아이콘 색상 설정(대표색상 설정) 사용중 아이콘 목록 / 초기화 Btn 그늘집 이미지 추가·홀 위치 설정(코스보기 내 노출) | F14: O
A15: 13 | C15: 카트이동경로 확인 | D15: – | E15: 카트 이동 경로 조회 — 상세 기획 미정의 | F15: X | G15: 미정의
A16: 14 | B16: 태블릿 운영 관리 | C16: 태블릿 기능 설정 | D16: 경기 진행 설정 | E16: 태블릿 기능 토글 목록: - 고객확인서 팝업(라운드 시작 시) - 중대재해 확인서 - 추가 확인서(필수/선택) - 드론영상 텍스트 음성 변환 - 관제 긴급 호출 - 관제 긴급 메시지 - 전체 관제화면 보기 - 날씨 확인 - 다음 코스 대기 카트 표시(8번홀 진입 시) - 그린 팝업 전체/활성화/비활성화 기능 수 카드 요약 표시 토글 26.5.7 변경 반영 | F16: O
A17: 15 | D17: 고객 확인서 관리 | E17: 라운드 시작 전 팝업 고객확인서 내용 관리 | F17: O
A18: 16 | D18: 중대재해 확인서 | E18: 2022.01.27 시행 중대재해처벌법 안내 문구 관리 기존 기능 / UI만 변경 | F18: O
A19: 17 | D19: 추가 확인서 | E19: 추가 확인서 항목 커스터마이징(캐디모드 전용) 태블릿 서명 전 확인용 노출 | F19: O
A20: 18 | D20: 잠금 모드 설정 | E20: 태블릿 잠금 모드 설정 | F20: △ | G20: 상세 미정의
A21: 19 | C21: 메시지 관리 | D21: – | E21: 센터 메시지 관리 기획서 오류로 개발4팀 문의 예정(25.5.11) | F21: X | G21: 개발 문의 필요
A22: 20 | C22: 홀 이벤트 관리 | D22: – | E22: 홀 이벤트 설정 관리 — 상세 기획 미정의 | F22: X | G22: 미정의
A23: 21 | B23: 홀맵 관리 | C23: 홀맵 구역 설정 | D23: – | E23: 홀맵구역 표 조회(기존 기능) '뒷카트알림' 타이틀 수정 구역관리 레이어팝업: - 코스/홀/파 표시 - 지도옵션(지도/위성/홀맵/정보 radio, 확대축소) - 홀맵 옵션(신규): 등록 홀맵 기준 지형 표시, 확대/축소 - 위험구역 설정 - 플레이 영역 설정(OB 설정·PA 설정 — 점으로 선 그리기) - 거리표시 지점 설정(신규 — 주황색 점, 거리표시 팝업) - 특정위치 알림 설정(초록색 점, 카트패스 선 위) - 뒷카트 알림 설정(영역 잡기, 전체면적·총거리 자동계산, 구역추가 팝업) - 다음 홀 방향 설정(카트패스 선 위 점 찍기) - 경로 위 포인트 등록 | F23: O | G23: 신규 기능 다수
A24: 22 | C24: 카트패스 진입여부 설정 | D24: – | E24: 페어웨이 진입 알림 전체 설정(활성화/비활성화) 코스별 페어웨이 진입 가능여부 설정 | F24: O
A25: 23 | C25: 티샷 유의 거리 설정 | D25: – | E25: 티샷 유의 거리 설정 — 상세 기획 미정의 | F25: X | G25: 미정의
A26: 24 | C26: 홀맵 미리보기 | D26: – | E26: 등록된 홀맵 미리보기 — 상세 기획 미정의 | F26: X | G26: 미정의
A27: 25 | B27: 코스 운영 관리 | C27: 핀 포지션 관리 | D27: – | E27: 핀 포지션 등록·수정·삭제 관리 | F27: O
A28: 26 | C28: 핀 포지션 변경이력 | D28: – | E28: 핀 포지션 변경 이력 조회 | F28: O
A29: 27 | C29: 핀 포지션 분석 | D29: – | E29: 핀 포지션 분석 데이터 조회 | F29: O
A30: 28 | C30: 코스 분석 | D30: – | E30: 코스 분석 데이터 조회·관리 | F30: O
A31: 29 | C31: 그린 스피드 | D31: – | E31: 그린 스피드 입력·조회 | F31: O
A32: 30 | C32: 골프장 소식 | D32: – | E32: 골프장 소식 등록·관리 | F32: O
A33: 31 | B33: 경기 진행 관리 | C33: 진행시간 표준 설정 | D33: – | E33: 진행시간 표준값 설정·저장 | F33: O
A34: 32 | C34: 진행시간 실시간 | D34: – | E34: 실시간 진행시간 조회 | F34: O
A35: 33 | C35: 진행시간 조회 | D35: – | E35: 기간별 진행시간 조회·검색 | F35: O
A36: 34 | C36: 진행시간 통계 | D36: – | E36: 진행시간 통계 조회·내보내기 | F36: O
A37: 35 | B37: 캐디 관리 | C37: 캐디 리스트 | D37: – | E37: 캐디 현황 조회 하우스/외부 캐디 비율 차트 활동/비활동 캐디 비율 차트 회원/비회원 캐디 비율 차트 | F37: O
A38: 36 | C38: 캐디 등록 관리 | D38: – | E38: 캐디 등록·수정·삭제 관리 | F38: O
A39: 37 | C39: 캐디 실적 | D39: – | E39: 캐디별 실적 조회·통계 | F39: O
A40: 38 | B40: 캐디피 관리 | C40: 캐디피 설정 | D40: – | E40: 캐디피 금액 설정 감사팁 결제 여부 설정 | F40: O
...

Sheet 시트30
B2: 분석여부 = 분석 JSON 존재 / 스크립트 = suite+spec 존재
B3: 대메뉴 | C3: 1depth | D3: 분석(Z) | E3: 스크립트(AA)
B4: 홈 | C4: 홈 | D4: O | E4: O
B5: 라운드관리 | C5: 내장 현황/내장 통계/전체라운드/라운드 설정/카트관리/홀별정산관리 | D5: O | E5: O
B6: 라운드관리 | C6: 단체라운드 | D6: O | E6: X(범위제외)
B7: 관제 관리 | C7: 아이콘 관리/라이브채팅 공지 조회/카트이동경로 확인 | D7: O | E7: O
B8: 관제 관리 | C8: 메시지 기록 조회 | D8: O | E8: X(빈 화면·미구현 의심)
B9: 관제 관리 | C9: 관제 모니터 | D9: X | E9: X (신규·범위제외 가능)
B10: 태블릿 운영 관리 | C10: 태블릿 기능 설정 | D10: O | E10: O
B11: 태블릿 운영 관리 | C11: 메시지 관리 / 홀 이벤트 관리 | D11: O | E11: X ← 진행
B12: 홀맵 관리 | C12: 홀맵 구역 설정/카트패스 진입여부/티샷 유의 거리/홀맵 미리보기 | D12: O | E12: X ← 진행
B13: 코스 운영 관리 | C13: 핀 포지션 관리/변경이력/분석, 코스 분석, 그린스피드, 골프장소식 | D13: O | E13: X ← 진행
B14: 경기 진행 관리 | C14: 진행시간 표준설정/실시간/조회/통계 | D14: O | E14: X ← 진행
... B18: 캐디피/식음/고객평가/대회/계정 관리 | C18: (전체) | D18: X | E18: X (분석 미수행)
B19: → "분석 O · 스크립트 X" = 이어서 작업 대상: 20개 (태블릿2 + 홀맵4 + 코스6 + 경기진행4 + 캐디3 + 배토기록1). 메시지 기록 조회·단체라운드는 제외(사유 명시).

Sheet HOME
A1: No. | C1: 화면 | F1: 기능 | G1: 사전 조건 | H1: 절차 | I1: 예상결과 | J1: 기획서 | K1: QA 확인 결과 | L1: JIRA | M1: 비고 | N1: 담당자
B2: 0 dapth | C2: 1 depth | D2: 2 depth | E2: 3 depth
A3: =COUNTA($I$3:$I3) -> 1 | B3: HOME | C3: HOME | F3: 제공정보 | H3: 1. 홈 화면 진입 | I3: 1. 헤더 영역 제공 2. 최신 공지 글 제공 3. 좌측 메뉴 아코디언 모두 접힌 상태로 제공 | J3: 공통 및 메인 | K3: PASS
A4: =COUNTA($I$3:$I4) -> 2 | B4: HOME | C4: 헤더 | F4: GNB (공통) | H4: 1. 홈 진입 후 GNB 영역 확인 | I4: 1. 왼쪽 상단에 타이틀 제공 2. 타이틀 우측에 로그인한 골프장명 제공 - SMARTSCORE 경기관제 | $골프장명$ 3. 언어 선택 드롭다운 박스 제공 4. 프로필 진입(사진) 버튼 제공 | J4: 공통 및 메인 | K4: PASS
A5: =COUNTA($I$3:$I5) -> 3 | B5: HOME | C5: 헤더 | H5: 1. 언어 선택 드롭다운 박스 선택 | I5: 1. 선택 가능 언어 항목 제공되고 선택 시 해당 언어로 변경 | J5: 공통 및 메인 | K5: PASS
A6: =COUNTA($I$3:$I6) -> 4 | B6: HOME | C6: 헤더 | H6: 1. 프로필 버튼 선택 | I6: 1. 마이 페이지 팝업 제공 - 아이디 / 부서 / 휴대폰 / 이메일 2. 로그아웃 버튼 제공 - 선택 시 로그아웃 됨 | J6: 공통 및 메인 | K6: FAIL | L6: https://smartscoretech.atlassian.net/browse/QA-14823 | M6: 클라우드 제공 마이페이지와 상이
A7: =COUNTA($I$3:$I7) -> 5 | B7: HOME | C7: 메인 | F7: 제공정보 | H7: 1. 홈 화면 진입 | I7: 1. 최신 등록 공지글 제공 - 공지사항 제목 영역 제공 - 공지사항 본문 영역 제공 2. 공지사항 리스트 제공 | J7: 공통 및 메인 | K7: PASS
A8: =COUNTA($I$3:$I8) -> 6 | B8: HOME | C8: 메인 | F8: 공지사항 제목 | H8: 1. 공지사항 제목 영역 확인 | I8: 1. 좌/우 이동 버튼 제공 - 이전/다음 글 존재할 경우 노출 2. 공지글 제목 표시 3. 공지글 작성/수정 최종 일시 제공 | J8: 공통 및 메인 | K8: PASS
A9: =COUNTA($I$3:$I9) -> 7 | B9: HOME | C9: 메인 | G9: 1. 이전/다음 글 존재 | H9: 1. 공지사항 제목 영역 2. 이전/다음 버튼 선택 | I9: 1. 이전/다음글 제공 | J9: 공통 및 메인 | K9: PASS
A10: =COUNTA($I$3:$I10) -> 8 | B10: HOME | C10: 메인 | G10: 1. 공지글 수정 | H10: 1. 공지글 작성/수정 일시 영역 확인 | I10: 1. 수정한 최종 일시 제공 | J10: 공통 및 메인 | K10: PASS
A11: =COUNTA($I$3:$I11) -> 9 | B11: HOME | C11: 메인 | F11: 공지사항본문 | H11: 1. 공지사항 본문 영역 확인 | I11: 1. 최신 등록 공지글 제공 - 공지글 제목 표시 - 해당 공지글작성/수정 최종 일시 표시 - 공지글 본문 제공 | J11: 공통 및 메인 | K11: PASS
A12: =COUNTA($I$3:$I12) -> 10 | B12: HOME | C12: 메인 | G12: 1. 공지글 수정 | H12: 1. 공지사항 본문 영역 확인 | I12: 1. 수정 사항 반영되어 제공 2. 수정한 최종 일시 제공 | J12: 공통 및 메인 | K12: PASS
A13: =COUNTA($I$3:$I13) -> 11 | B13: HOME | C13: 메인 | F13: 공지사항 리스트 | H13: 1. 공지사항 리스트 확인 | I13: 1. 등록된 공지사항 리스트 제공 - 공지글 제목 표시 - 해당 공지글작성/수정 최종 일시 표시 | J13: 공통 및 메인 | K13: PASS
A14: =COUNTA($I$3:$I14) -> 12 | B14: HOME | C14: 메인 | H14: 1. 공지글 선택 | I14: 1. 선택한 공지글이 공지사항 본문 영역에 제공 | J14: 공통 및 메인 | K14: PASS

Sheet 라운드 관리
A1: No. | C1: 화면 | F1: 기능 | G1: 사전 조건 | H1: 절차 | I1: 예상결과 | J1: 기획서 | K1: QA 확인 결과 | L1: JIRA | M1: 비고 | N1: 담당자
B2: 0 dapth | C2: 1 depth | D2: 2 depth | E2: 3 depth
A3: =COUNTA($I$3:$I3) -> 1 | B3: 라운드 관리 | C3: 내장 현황 | F3: 제공정보 | H3: 1. 라운드 관리 2. 내장 현황 선택 | I3: 1. 내장 현황 설명 영역 제공 - [데이터 마케팅 바로가기] 버튼 노출 - [도움말] 버튼 노출 2. 내장 현황 테이블 제공 - [내보내기] 버튼 노출 | J3: 내장 현황 | K3: PASS | L3: https://smartscoretech.atlassian.net/browse/QA-14828
A4: =COUNTA($I$3:$I4) -> 2 | B4: 라운드 관리 | C4: 내장 현황 | F4: 내장 현황 설명 | H4: 1. 내장 현황 설명 확인 | I4: 1. 내장 현황 설명 제공 - 문구: 골프장에 방문한 일별 내장객수와 스마트스코어 회원수, 출력량, 출력률 등을 확인하고 엑셀로 다운로드할 수 있습니다. 90일 동안의 기록만 확인 가능합니다. 스마트스코어 회원이 어플로 라운드를 전송받는 경우, 해당 회원정보(성별, 연령, 지역)를 골프장에서 타겟마케팅의 목적으로 활용할 수 있습니다. 내장객에게 스마트스코어 어플을 추천하고, 라운드기록을 전송받을 수 있도록 안내해 주세요. | J4: 내장 현황 | K4: PASS
A5: =COUNTA($I$3:$I5) -> 3 | B5: 라운드 관리 | C5: 내장 현황 | D5: 도움말 버튼 | F5: 도움말 버튼 | H5: 1. [도움말] 버튼 선택 | I5: 1. 도움말 제공 - 문구: 스마트스코어가 보유한 전국골프장의 내장/라운드 데이타를 제공하여 골프장의 매출증대에 활용하실 수 있는 서비스를 제공받으실 수 있습니다. | J5: 내장 현황 | K5: PASS
A6: =COUNTA($I$3:$I6) -> 4 | B6: 라운드 관리 | C6: 내장 현황 | D6: 데이터 마케팅 바로가기 | F6: 데이터 마케팅 바로가기 버튼 | H6: 1. [데이터 마케팅 바로가기] 버튼 선택 | I6: 1. 데이터 마케팅 화면이 새 탭/창으로 오픈 2. 현재 내장 현황 화면은 유지 | J6: 내장 현황 | K6: PASS
A7: =COUNTA($I$3:$I7) -> 5 | B7: 라운드 관리 | C7: 내장 현황 | D7: 테이블 | F7: 제공정보 | H7: 1. 테이블 영역 확인 | I7: 1. 내장 현황 테이블 제공 2. 테이블 컬럼 - 날짜 / 총 내장객 / 내장객 남여 / 유효 내장객 / 기존 SS회원 / 신규 SS회원 / 일일 SS회원 / SS회원 비율 / 출력 횟수 / 출력률 | J7: 내장 현황 | K7: PASS | L7: https://smartscoretech.atlassian.net/browse/QA-14831
A8: =COUNTA($I$3:$I8) -> 6 | B8: 라운드 관리 | C8: 내장 현황 | D8: 테이블 | F8: 정렬 및 조회 기간 | G8: 1. 내장 현황 데이터 90일 이내 존재 | H8: 1. 테이블 영역 2. 날짜 컬럼 및 정렬 순서 확인 | I8: 1. 날짜 내림차순(최신순) 정렬 2. 최근 90일 이내 데이터만 표시됨 | J8: 내장 현황 | K8: PASS
A9: =COUNTA($I$3:$I9) -> 7 | B9: 라운드 관리 | C9: 내장 현황 | D9: 테이블 | G9: 1. 내장 현황 데이터 90일 이전 존재 | H9: 1. 테이블 영역 확인 | I9: 1. 91일 이전 데이터 미노출 | J9: 내장 현황 | K9: PASS
A10: =COUNTA($I$3:$I10) -> 8 | B10: 라운드 관리 | C10: 내장 현황 | D10: 테이블 | F10: 총 내장객 | H10: 1. 총 내장객 영역 확인 | I10: 1. 해당일자의 총 내장객 정보 제공 2. 회원 여부 상관 없이 제공 | J10: 내장 현황 | K10: PASS | M10: 로드힐즈에서 확인
A11: =COUNTA($I$3:$I11) -> 9 | B11: 라운드 관리 | C11: 내장 현황 | D11: 테이블 | F11: 내장객 남/여 | G11: 1. 당일 남/여 내장객 각 1명 이상 존재 | H11: 1. 내장객 남/여 영역 확인 | I11: 1. 남/여 내장객 수 정상 표시됨 2. 남+여 합산 = 해당일 총 내장객 수 | J11: 내장 현황 | K11: PASS | M11: 로드힐즈에서 확인 | N11: 태블릿 성별을 가져옴
A12: =COUNTA($I$3:$I12) -> 10 | B12: 라운드 관리 | C12: 내장 현황 | D12: 테이블 | F12: 유효 내장객 | G12: 1. 회원/비회원 - 18 홀 완료 내장객 존재 - 18 홀 미완료 내장객 존재 | H12: 1. 유효 내장객 영역 확인 | I12: 1. 18홀 완료한 내장객 수 제공 | J12: 내장 현황 | K12: PASS | L12: https://smartscoretech.atlassian.net/browse/QA-14844 | M12: 6/2 로드힐즈에서 확인
A13: =COUNTA($I$3:$I13) -> 11 | B13: 라운드 관리 | C13: 내장 현황 | D13: 테이블 | F13: 기존 SS회원 | H13: 1. 기존 SS회원 영역 확인 | I13: 1. 기존 스마트스코어 회원 수 제공 | J13: 내장 현황 | K13: PASS | M13: 로드힐즈에서 확인
A14: =COUNTA($I$3:$I14) -> 12 | B14: 라운드 관리 | C14: 내장 현황 | D14: 테이블 | F14: 신규 SS회원 | H14: 1. 신규 SS회원 영역 확인 | I14: 1. 해당일 신규로 스마트스코어 가입한 회원 수 제공 | J14: 내장 현황 | K14: PASS | L14: https://smartscoretech.atlassian.net/browse/QA-14844 | M14: 6/2 로드힐즈에서 확인
A15: =COUNTA($I$3:$I15) -> 13 | B15: 라운드 관리 | C15: 내장 현황 | D15: 테이블 | F15: 일일 SS회원 | H15: 1. 일일 SS회원 영역 확인 | I15: 1. 해당일 기준 기존 스마트스코어 회원 + 신규 스마트스코어 회원 수 제공 | J15: 내장 현황 | K15: PASS | L15: https://smartscoretech.atlassian.net/browse/QA-14844 | M15: 6/2 로드힐즈에서 확인
A16: =COUNTA($I$3:$I16) -> 14 | B16: 라운드 관리 | C16: 내장 현황 | D16: 테이블 | F16: SS회원 비율 | G16: 1. 유효내장객, 기존SS회원, 신규SS회원 데이터 존재 | H16: 1. SS 회원 비율 영역 확인 | I16: 1. SS회원 비율 = (기존SS회원+신규SS회원)/유효내장객×100 | J16: 내장 현황 | K16: PASS | M16: 반올림?
A17: =COUNTA($I$3:$I17) -> 15 | B17: 라운드 관리 | C17: 내장 현황 | D17: 테이블 | F17: 출력 횟수 | H17: 1. 출력 횟수 영역 확인 | I17: 1. 스코어카드 출력 횟수 제공 | J17: 내장 현황 | K17: PASS | M17: 6/2 킹즈락 데이터 확인
A18: =COUNTA($I$3:$I18) -> 16 | B18: 라운드 관리 | C18: 내장 현황 | D18: 테이블 | F18: 출력률 | G18: 1. 유효내장객, 출력횟수 데이터 존재 | H18: 1. 출력률 영역 확인 | I18: 1. 출력률 = (출력횟수/유효내장객)×100 | J18: 내장 현황 | K18: PASS | L18: https://smartscoretech.atlassian.net/browse/QA-14831 | M18: 비노출
A19: =COUNTA($I$3:$I19) -> 17 | B19: 라운드 관리 | C19: 내장 현황 | D19: 내보내기 | F19: 내보내기 | G19: 1. 내장 현황 데이터 1건 이상 존재 | H19: 1. [내보내기] 버튼 선택 | I19: 1. 엑셀 파일 다운로드됨 2. 파일 내 컬럼 구성이 화면 테이블과 일치함 3. 최근 90일 기록 전체 포함됨 | J19: 내장 현황 | K19: PASS
A20: =COUNTA($I$3:$I20) -> 18 | B20: 라운드 관리 | C20: 내장 통계 | F20: 제공정보 | G20: 관제 어드민 로그인 완료 | H20: 1. 라운드 관리 2. 내장 통계 선택 | I20: 1. 내장 통계 설명 영역 제공 - [데이터 마케팅 바로가기] 버튼 노출 2. 조회 기간 선택 영역 노출됨 - [초기화][적용] 버튼 제공 3. 카드 요약 영역 제공 4. 필터 버튼 제공 5. 일별 내장 통계 테이블 영역 제공 | J20: 내장 통계 | K20: PASS
A21: =COUNTA($I$3:$I22) -> 20 | B21: 라운드 관리 | C21: 내장 통계 | E21: - | F21: 내장 통계 설명 | H21: 1. 내장 통계 설명 확인 | I21: 1. 내장 통계 설명 제공 - 문구: 스마트스코어 회원이 내장하여 라운드기록을 전송받는 경우, 골프장에서는 해당 회원의 정보를 활용하여 타겟마케팅이 가능합니다. 스마트스코어 회원이 라운드기록을 전송받은 데이타에 근거하여 골프장 내장객의 성격과 추이를 확인할 수 있습니다. | J21: 내장 통계 | K21: PASS
A22: =COUNTA($I$3:$I22) -> 20 | B22: 라운드 관리 | C22: 내장 통계 | D22: 데이터 마케팅 바로가기 | F22: 데이터 마케팅 바로가기 버튼 | H22: 1. [데이터 마케팅 바로가기] 버튼 선택 | I22: 1. 데이터 마케팅 화면이 새 탭/창으로 오픈 2. 현재 내장 현황 화면은 유지 | J22: 내장 통계 | K22: PASS
A23: =COUNTA($I$3:$I23) -> 21 | B23: 라운드 관리 | C23: 내장 통계 | D23: 검색 영역 | E23: - | F23: 조회기간 기본값 | H23: 1. 조회기간 영역 확인 | I23: 1. 기간 자동 세팅 제공 - 기본값: 과거 30일 전 ~ 현재일 | J23: 내장 통계 | K23: FAIL | L23: https://smartscoretech.atlassian.net/browse/QA-14840 | M23: 데이터가 있는 날 ~ 오늘 날로 제공
A24: =COUNTA($I$3:$I24) -> 22 | B24: 라운드 관리 | C24: 내장 통계 | D24: 검색 영역 | F24: 조회기간 적용 | H24: 1. 조회기간 영역 선택 | I24: 1. 데이트 피커 제공 | K24: PASS
A25: =COUNTA($I$3:$I25) -> 23 | B25: 라운드 관리 | C25: 내장 통계 | D25: 검색 영역 | H25: 1. 조회기간 영역 2. 기간 설정 3. [적용] 버튼 선택 | I25: 1. 설정 기간 기준 전체 영역 갱신 - 요약 카드 - 일별 내장 통계 테이블 | J25: 내장 통계 | K25: PASS
A26: =COUNTA($I$3:$I26) -> 24 | B26: 라운드 관리 | C26: 내장 통계 | D26: 검색 영역 | F26: 조회기간 경계값 | G26: 1. 조회 기간 1년 설정 - 364일 | H26: 1. 조회기간 영역 2. 기간 설정 3. [적용] 버튼 선택 | I26: 1. 설정 기간 기준 전체 영역 갱신 - 요약 카드 - 일별 내장 통계 테이블 | J26: 내장 통계 | K26: PASS
A27: =COUNTA($I$3:$I27) -> 25 | B27: 라운드 관리 | C27: 내장 통계 | D27: 검색 영역 | G27: 1. 조회 기간 1년 설정 - 365일 | H27: 1. 조회기간 영역 2. 기간 설정 3. [적용] 버튼 선택 | I27: 1. 설정 기간 기준 전체 영역 갱신 - 요약 카드 - 일별 내장 통계 테이블 | J27: 내장 통계 | K27: PASS
A28: =COUNTA($I$3:$I28) -> 26 | B28: 라운드 관리 | C28: 내장 통계 | D28: 검색 영역 | G28: 1. 조회 기간 1년 초과 설정 - 366일 | H28: 1. 조회기간 영역 2. 기간 설정 3. [적용] 버튼 선택 | I28: 1. 조회 불가 얼럿 제공 - 문구: 최대 조회 가능 기간은 1년입니다. | J28: 내장 통계 | K28: PASS | L28: https://smartscoretech.atlassian.net/browse/QA-14841 | M28: 오류 메시지 표시?
A29: =COUNTA($I$3:$I29) -> 27 | B29: 라운드 관리 | C29: 내장 통계 | D29: 검색 영역 | F29: 조회 기간 역순 | G29: 1. 조회 기간 역순 설정 - 시작일 > 종료일 | H29: 1. 조회기간 영역 2. 기간 설정 3. [적용] 버튼 선택 | I29: 1. 날짜 선택 제한 처리됨 | J29: 내장 통계 | K29: PASS | M29: 오류 메시지 표시?
A30: =COUNTA($I$3:$I30) -> 28 | B30: 라운드 관리 | C30: 내장 통계 | D30: 검색 영역 | F30: 초기화 | H30: 1. 조회기간 영역 2. 기간 설정 3. [초기화] 버튼 선택 | I30: 1. 설정한 기간이 초기화되어 기본값으로 제공 됨 | J30: 내장 통계 | K30: N/T | L30: https://smartscoretech.atlassian.net/browse/QA-14840 | M30: 요약카드, 테이블 모두?
A31: =COUNTA($I$3:$I31) -> 29 | B31: 라운드 관리 | C31: 내장 통계 | D31: 카드 요약 | F31: 제공 정보 | H31: 1. 카드 요약 영역확인 | I31: 1. 3개 카드 제공 - 총 스스회원 내장객 - 일 평균 스스 회원수 - 남성/여성 비중 | J31: 내장 통계 | K31: PASS
A32: =COUNTA($I$3:$I32) -> 30 | B32: 라운드 관리 | C32: 내장 통계 | D32: 카드 요약 | F32: 총 스스 회원 내장객 | H32: 1. 총 스스 회원 내장객 영역 확인 | I32: 1. 조회기간 내 스코어 전송한 스스 회원 합계 표시 - 타이틀: 총 스스 회원 내장객 - 서브 라벨: 조회기간 기준 합계 | J32: 내장 통계 | K32: PASS | M32: 스코어 전송을 안한 회원도 포함일수도..
A33: =COUNTA($I$3:$I33) -> 31 | B33: 라운드 관리 | C33: 내장 통계 | D33: 카드 요약 | G33: 1. 조회 기간 내 동일인이 2회 이상 라운드 | H33: 1. 총 스스 회원 내장객 영역 확인 | I33: 1. 해당 회원은 1명으로 카운팅 | J33: 내장 통계 | K33: PASS | L33: https://smartscoretech.atlassian.net/browse/QA-14879 | M33: 6/2 로드힐스/한지연으로 확인
A34: =COUNTA($I$3:$I34) -> 32 | B34: 라운드 관리 | C34: 내장 통계 | D34: 카드 요약 | F34: 일평균 스스 회원수 | H34: 1. 일평균 스스 회원수 영역 확인 | I34: 1. 총 스스 회원 내장객 수 ÷ 조회기간 일수 계산값 표시 - 타이틀: 일평균 스스 회원수 - 라벨: n일 평균 | J34: 내장 통계 | K34: PASS | L34: https://smartscoretech.atlassian.net/browse/QA-14849
A35: =COUNTA($I$3:$I35) -> 33 | B35: 라운드 관리 | C35: 내장 통계 | D35: 카드 요약 | F35: 남성/여성 비중 | H35: 1. 남성/여성 비중 영역 확인 | I35: 1. 조회 기간 내 총 스스 회원 내장객의 남성/여성을 비율로 표시 - 타이틀: 남성/여성 비중 - 서브라벨: 스스 회원 기준 | J35: 내장 통계 | K35: PASS | N35: 개인앱 성별 가져옴
A36: =COUNTA($I$3:$I36) -> 34 | B36: 라운드 관리 | C36: 내장 통계 | D36: 카드 요약 | G36: 1. 성별 미입력 내장객: Y | H36: 1. 남성/여성 비중 영역 확인 | I36: 1. 남성/여성 비중에 반영되지 않음 | J36: 내장 통계 | K36: PASS | M36: 6/2 로드힐스 확인
A37: =COUNTA($I$3:$I37) -> 35 | B37: 라운드 관리 | C37: 내장 통계 | D37: 필터 버튼 | F37: 제공정보 | H37: 1. 필터 버튼 영역 확인 | I37: 1. 필터 버튼 제공 - [전체보기] (디폴트) - [성별만 보기] - [연령별만 보기] | J37: 내장 통계 | K37: PASS
A38: =COUNTA($I$3:$I38) -> 36 | B38: 라운드 관리 | C38: 내장 통계 | D38: 필터 버튼 | F38: [전체보기] 버튼 | H38: 1. [전체보기] 버튼 선택 2. 일별 내장 통계 테이블 확인 | I38: 1. [전체보기] 버튼 기본 활성화 상태 2. 일자, 스스 회원수, 성별(남자/여자/기타), 연령별 컬럼 표시 | J38: 내장 통계 | K38: PASS
A39: =COUNTA($I$3:$I39) -> 37 | B39: 라운드 관리 | C39: 내장 통계 | D39: 필터 버튼 | F39: [성별만 보기] 버튼 | H39: 1. [성별만 보기] 버튼 선택 2. 일별 내장 통계 테이블 확인 | I39: 1. [성별만 보기] 버튼 기본 활성화 상태 2. 일자, 스스 회원수, 남자, 여자, 기타 컬럼만 표시 | J39: 내장 통계 | K39: PASS
A40: =COUNTA($I$3:$I40) -> 38 | B40: 라운드 관리 | C40: 내장 통계 | D40: 필터 버튼 | F40: [연령별만 보기] 탭 전환 시 컬럼 변경 | H40: 1. [연령별만 보기] 버튼 선택 2. 일별 내장 통계 테이블 확인 | I40: 1. [연령별만 보기] 활성화 2. 일자, 스스 회원수, 연령별 (~10, 11~20, 21~30, 31~40, 41~50, 51~60, 61~70, 71~80, 81~90, 90~, 기타) 컬럼만 표시 | J40: 내장 통계 | K40: PASS
...

Sheet 관제 관리
A1: No. | C1: 화면 | F1: 기능 | G1: 사전 조건 | H1: 절차 | I1: 예상결과 | J1: 기획서 | K1: QA 확인 결과 | L1: JIRA | M1: 비고 | N1: 담당자
B2: 0 dapth | C2: 1 depth | D2: 2 depth | E2: 3 depth
A3: =COUNTA($I$3:$I3) -> 1 | B3: 관제 관리 | C3: 관제 관리 | D3: - | E3: - | F3: 메뉴 확인 | G3: - | H3: 1. 관제 관리 대메뉴 선택 2. 메뉴 구성 확인 | I3: 1. 관제 관리의 메뉴가 제공됨 - 관제 팝업 (QA 제외 항목) - 메시지 기록 조회 - 라이브채팅 공지 조회 - 아이콘 관리 - 라이브채팅 공지 조회 - 카트 이동경로 확인? | J3: 관제 관리 | K3: FAIL | L3: QA-14818 | M3: 문구 수정 필요
A4: =COUNTA($I$3:$I4) -> 2 | B4: 관제 관리 | C4: 메시지 기록 조회 | D4: - | E4: - | F4: 제공 정보 | G4: - | H4: 1. [메시지 기록 조회] 메뉴 진입 2. 제공 정보 확인 | I4: 1. 메시지 기록 조회 메뉴 제공됨(클라우드 UI) - 타이틀 : 메시지 기록 조회 - 안내 문구 영역 - 대화내용 검색 영역 - 대화내용 영역 | J4: 메시지 기록 조회
A5: =COUNTA($I$3:$I5) -> 3 | B5: 관제 관리 | D5: 안내문구 영역 | E5: - | F5: 안내 문구 | G5: - | H5: 1. 안내 문구 확인 | I5: 1. 변경된 안내문구 제공됨 - 문구 : 센터와 태블릿 간의 메시지 기록을 조회할 수 있습니다. 단, 한 달 이내의 메시지 기록만 보관됩니다. | J5: 메시지 기록 조회
A6: =COUNTA($I$3:$I6) -> 4 | B6: 관제 관리 | D6: 대화내용 검색 영역 | E6: - | F6: 대화내용 검색 | G6: 1. 대화 내용 : X | H6: 1. 대화내용 입력 2. [검색] 버튼 선택 | I6: 1. 검색 결과 제공되지 않음 - 문구 : 검색결과가 없습니다. | J6: 메시지 기록 조회
A7: =COUNTA($I$3:$I7) -> 5 | B7: 관제 관리 | E7: - | G7: 1. 대화 내용 : O | H7: 1. 대화내용 입력 2. [검색] 버튼 선택 | I7: 1. 검색한 결과가 제공됨 - 해당 내용이 있는 화면으로 스크롤됨 | J7: 메시지 기록 조회
A8: =COUNTA($I$3:$I8) -> 6 | B8: 관제 관리 | E8: - | G8: 1. 대화 내용 : X | H8: 1. 달력 버튼 선택 2. 대화 내용이 존재하지않는 날짜 선택 | I8: 1. 검색 결과 제공되지 않음 - 문구 : 검색결과가 없습니다. | J8: 메시지 기록 조회
A9: =COUNTA($I$3:$I9) -> 7 | B9: 관제 관리 | E9: - | G9: 1. 대화 내용 : O | H9: 1. 달력 버튼 선택 2. 대화 내용이 존재하는 날짜 선택 | I9: 1. 해당 날짜로 스크롤됨 | J9: 메시지 기록 조회
A10: =COUNTA($I$3:$I10) -> 8 | B10: 관제 관리 | D10: 대화창 영역 | E10: - | F10: 제공 정보 | G10: 1. 대화 내용 : X | H10: 1. 대화창 영역 확인 | I10: 1. 대화창이 제공되지 않음 | J10: 메시지 기록 조회
A11: =COUNTA($I$3:$I11) -> 9 | B11: 관제 관리 | E11: - | G11: 1. 대화 내용 : O | H11: 1. 대화창 영역 확인 | I11: 1. 대화 내용이 제공됨 - yyyy년 mm월 dd일 요일 - To. {대상자} - 대화 내용 - 오전/오후 hh:mm | J11: 메시지 기록 조회
A12: =COUNTA($I$3:$I12) -> 10 | B12: 관제 관리 | E12: - | F12: 스크롤 | H12: 1. 스크롤 동작 확인 | I12: 1. 대화창에서 스크롤 가능함 2. 스크롤 시 날짜별 확인 가능함 | J12: 메시지 기록 조회
A13: =COUNTA($I$3:$I13) -> 11 | B13: 관제 관리 | C13: 라이브채팅 공지 조회 | D13: - | E13: - | F13: 제공 정보 | G13: - | H13: 1. [라이브채팅 공지 조회] 메뉴 진입 2. 제공 정보 확인 | I13: 1. 라이브채팅 공지 조회 메뉴 제공됨(클라우드 UI) - 타이틀 : 라이브채팅 공지 조회 - 안내 문구 영역 - 대화내용 검색 영역 - 대화내용 영역 | J13: 라이브채팅 공지 조회 | K13: PASS | L13: QA-14829 | M13: UI 상이
A14: =COUNTA($I$3:$I14) -> 12 | B14: 관제 관리 | D14: 안내문구 영역 | E14: - | F14: 안내 문구 | G14: - | H14: 1. 안내 문구 확인 | I14: 1. 안내문구 제공됨 - 문구 : 라이브채팅의 공지사항 기록을 조회할 수 있습니다. 단, 한 달 이내의 공지사항만 보관됩니다. | J14: 라이브채팅 공지 조회 | K14: PASS
A15: =COUNTA($I$3:$I15) -> 13 | B15: 관제 관리 | D15: 대화내용 검색 영역 | E15: - | F15: 대화내용 검색 | G15: 1. 대화 내용 : X | H15: 1. 대화내용 입력 2. [검색] 버튼 선택 | I15: 1. 검색 결과 제공되지 않음 - 문구 : 검색결과가 없습니다. | J15: 라이브채팅 공지 조회 | K15: PASS | L15: QA-14829 | M15: 입력 후 검색 시 하얀 화면
A16: =COUNTA($I$3:$I16) -> 14 | B16: 관제 관리 | E16: - | G16: 1. 대화 내용 : O | H16: 1. 대화내용 입력 2. [검색] 버튼 선택 | I16: 1. 검색한 결과가 제공됨 - 해당 내용이 있는 화면으로 스크롤됨 | J16: 라이브채팅 공지 조회 | K16: PASS
A17: =COUNTA($I$3:$I17) -> 15 | B17: 관제 관리 | E17: - | G17: 1. 대화 내용 : X | H17: 1. 달력 버튼 선택 2. 대화 내용이 존재하지않는 날짜 선택 | I17: 1. 검색 결과 제공되지 않음 - 문구 : 검색결과가 없습니다. | J17: 라이브채팅 공지 조회 | K17: PASS
A18: =COUNTA($I$3:$I18) -> 16 | B18: 관제 관리 | E18: - | G18: 1. 대화 내용 : O | H18: 1. 달력 버튼 선택 2. 대화 내용이 존재하는 날짜 선택 | I18: 1. 해당 날짜로 스크롤됨 | J18: 라이브채팅 공지 조회 | K18: PASS
A19: =COUNTA($I$3:$I19) -> 17 | B19: 관제 관리 | D19: 대화창 영역 | E19: - | F19: 제공 정보 | G19: 1. 대화 내용 : X | H19: 1. 대화창 영역 확인 | I19: 1. 대화창이 제공되지 않음 | J19: 라이브채팅 공지 조회 | K19: N/A | M19: 테스트 데이터 존재하여 확인 불가
A20: =COUNTA($I$3:$I20) -> 18 | B20: 관제 관리 | E20: - | G20: 1. 대화 내용 : O | H20: 1. 대화창 영역 확인 | I20: 1. 대화 내용이 제공됨 - 대화 내용 - 오전/오후 hh:mm | J20: 라이브채팅 공지 조회 | K20: PASS
A21: =COUNTA($I$3:$I21) -> 19 | B21: 관제 관리 | E21: - | F21: 스크롤 | H21: 1. 스크롤 동작 확인 | I21: 1. 대화창에서 스크롤 가능함 2. 스크롤 시 날짜별 확인 가능함 | J21: 라이브채팅 공지 조회 | K21: PASS
A22: =COUNTA($I$3:$I22) -> 20 | B22: 관제 관리 | C22: 아이콘 관리 | D22: - | E22: - | F22: 제공 정보 | G22: - | H22: 1. [아이콘 관리] 메뉴 진입 2. 제공 정보 확인 | I22: 1. 아이콘 관리 메뉴 제공됨(클라우드 UI) - 타이틀 : 아이콘 관리 - 안내 문구 영역 - 기능 설정 영역 - 사용중 아이콘 영역 - 아이콘 라이브러리 영역 - 코스 별 아이콘 색상 설정 영역 - 관제팝업 내 그늘집 표시 영역 | J22: 아이콘 관리 | K22: PASS
A23: =COUNTA($I$3:$I23) -> 21 | B23: 관제 관리 | D23: - | E23: - | F23: 안내 문구 | G23: - | H23: 1. 안내 문구 확인 | I23: 1. 변경된 안내 문구 제공됨 - 문구 : 관제 화면에서 사용할 아이콘 선택 및 코스 색상을 선택할 수 있습니다. \n 또한, 관제 화면에 그늘집 이미지를 추가할 수 있습니다. | J23: 아이콘 관리 | K23: PASS | L23: QA-14821 | M23: 안내 문구 비제공
A24: =COUNTA($I$3:$I24) -> 22 | B24: 관제 관리 | D24: 기능 설정 영역 | E24: - | F24: 제공 정보 | G24: - | H24: 1. 기능 설정 영역 확인 | I24: 1. 기능 설정 영역 제공됨 - 안내 문구 영역 - [저장] 버튼 - 항목별 기능 설정 영역 a. 관제 지도 아이콘 시인성 향상 b. 아이콘 관리 | J24: 아이콘 관리 | K24: PASS
A25: =COUNTA($I$3:$I25) -> 23 | B25: 관제 관리 | E25: - | F25: 안내 문구 | G25: - | H25: 1. 안내 문구 확인 | I25: 1. 안내 문구 제공됨 - 문구 : 관제지도 아이콘 시인성 향상 및 아이콘 관리 기능의 사용 여부를 설정합니다. | J25: 아이콘 관리 | K25: PASS
A26: =COUNTA($I$3:$I26) -> 24 | B26: 관제 관리 | E26: - | F26: 설정_관제지도 아이콘 시인성 향상 | G26: - | H26: 1. 관제지도 아이콘 시인성 향상 확인 | I26: 1. 관제지도 아이콘 시인성 향상 제공됨 - 기능명 : 관제지도 아이콘 시인성 향상 - 상세설명 : 관제팝업 지도보기 내, 카트에 배정된 아이콘 시인성 상향을 위한 기능입니다. (예시 사진 노출) - 설정 : 라디오 버튼(사용 / 사용안함) ON/OFF 토글 | J26: 아이콘 관리 | K26: PASS
A27: =COUNTA($I$3:$I27) -> 25 | B27: 관제 관리 | E27: - | G27: - | H27: 1. [사용] 선택 2. [저장] 버튼 선택 | I27: 1. 설정 가능함 | J27: 아이콘 관리 | K27: PASS
A28: =COUNTA($I$3:$I28) -> 26 | B28: 관제 관리 | E28: - | G28: - | H28: 1. [사용안함] 선택 2. [저장] 버튼 선택 | I28: 1. 설정 가능함 | J28: 아이콘 관리 | K28: PASS
A29: =COUNTA($I$3:$I29) -> 27 | B29: 관제 관리 | E29: - | F29: 설정_아이콘 관리 | G29: - | H29: 1. 아이콘 관리 확인 | I29: 1. 아이콘 관리 제공됨 - 기능명 : 아이콘 관리 - 상세설명 : 관제 화면에서 사용할 아이콘을 선택할 수 있습니다. \n 아이콘의 이름 및 형태 수정이 가능하며, 최소 6개, 최대 15개까지 선택이 가능합니다. - 설정 : 라디오 버튼(사용 / 사용안함) ON/OFF 토글 | J29: 아이콘 관리 | K29: PASS
A30: =COUNTA($I$3:$I30) -> 28 | B30: 관제 관리 | E30: - | G30: - | H30: 1. [사용] 선택 2. [저장] 버튼 선택 | I30: 1. 사용으로 설정 시 하단에 아이콘 라이브러리 설정이 가능함 | J30: 아이콘 관리 | K30: PASS
A31: =COUNTA($I$3:$I31) -> 29 | B31: 관제 관리 | E31: - | G31: - | H31: 1. [사용안함] 선택 2. [저장] 버튼 선택 | I31: 1. 사용안함으로 설정 시 하단에 아이콘 라이브러리 설정 불가함 | J31: 아이콘 관리 | K31: PASS
A32: =COUNTA($I$3:$I32) -> 30 | B32: 관제 관리 | E32: - | F32: 관제 연동 | G32: 1. 시인성 향상 : OFF 2. 아이콘 관리 : OFF | H32: 1. 관제 페이지에서 카트 아이콘 확인 | I32: 1. 카트에 아이콘 비제공됨 | J32: 아이콘 관리 | K32: N/A | M32: 카트 연동 QA 제외
A33: =COUNTA($I$3:$I33) -> 31 | B33: 관제 관리 | E33: - | G33: 1. 시인성 향상 : OFF 2. 아이콘 관리 : ON | H33: 1. 관제 페이지에서 카트 아이콘 확인 | I33: 1. 카트에 아이콘명 제공됨(아이콘은 비제공) | J33: 아이콘 관리 | K33: N/A | M33: 카트 연동 QA 제외
A34: =COUNTA($I$3:$I34) -> 32 | B34: 관제 관리 | E34: - | G34: 1. 시인성 향상 : ON 2. 아이콘 관리 : OFF | H34: 1. 관제 페이지에서 카트 아이콘 확인 | I34: 1. 카트에 아이콘 비제공됨 | J34: 아이콘 관리 | K34: N/A | M34: 카트 연동 QA 제외
A35: =COUNTA($I$3:$I35) -> 33 | B35: 관제 관리 | E35: - | G35: 1. 시인성 향상 : ON 2. 아이콘 관리 : ON | H35: 1. 관제 페이지에서 카트 아이콘 확인 | I35: 1. 카트에 아이콘+아이콘명 제공됨 | J35: 아이콘 관리 | K35: N/A | M35: 카트 연동 QA 제외
A36: =COUNTA($I$3:$I36) -> 34 | B36: 관제 관리 | C36: 아이콘 관리 | D36: 사용중 아이콘 & 아이콘 라이브러리 영역 | E36: - | F36: 제공 정보 | G36: - | H36: 1. 사용중 아이콘 영역 확인 2. 아이콘 라이브러리 영역 확인 | I36: 1. 사용중 아이콘 영역 제공됨 - 안내 문구 영역 - [저장][관제적용] 버튼 - 선택된 아이콘 영역 2. 아이콘 라이브러리 영역 제공됨 - 안내 문구 영역 - 아이콘 라이브러리 | J36: 아이콘 관리 | K36: PASS
A37: =COUNTA($I$3:$I37) -> 35 | B37: 관제 관리 | E37: - | F37: 아이콘 라이브러리 설정 | G37: - | H37: 1. 아이콘 라이브러리 안내 문구 확인 | I37: 1. 아이콘 라이브러리 안내 문구 제공됨 - 문구 : 공통 아이콘 세트 중 필요한 항목을 선택하여 관제 화면에 노출할 수 있습니다. | J37: 아이콘 관리 | K37: PASS
A38: =COUNTA($I$3:$I38) -> 36 | B38: 관제 관리 | G38: 1. 아이콘 관리 : OFF | H38: 1. 아이콘 라이브러리 항목 확인 | I38: 1. 아이콘 관리 OFF 시 비활성화됨 | J38: 아이콘 관리 | K38: PASS
A39: =COUNTA($I$3:$I39) -> 37 | B39: 관제 관리 | E39: - | G39: 1. 아이콘 관리 : ON | H39: 1. 아이콘 라이브러리 항목 확인 | I39: 1. 아이콘 관리 ON 시 활성화됨 | J39: 아이콘 관리 | K39: PASS
A40: =COUNTA($I$3:$I40) -> 38 | B40: 관제 관리 | E40: - | H40: 1. 입력 필드 확인 2. 아이콘명 입력 | I40: 1. 아이콘명 입력 가능함 | J40: 아이콘 관리 | K40: PASS
...

Sheet 태블릿 운영 관리
A1: No. | C1: 화면 | F1: 기능 | G1: 사전 조건 | H1: 절차 | I1: 예상결과 | J1: 기획서 | K1: QA 확인 결과 | L1: JIRA | M1: 비고 | N1: 담당자
B2: 0 dapth | C2: 1 depth | D2: 2 depth | E2: 3 depth
A3: =COUNTA($I$3:$I3) -> 1 | B3: 태블릿 운영 관리 | C3: 태블릿 운영 관리 | D3: - | E3: - | F3: 메뉴 확인 | G3: - | H3: 1. 태블릿 운영 관리 대메뉴 선택 2. 메뉴 구성 확인 | I3: 1. 태블릿 운영 관리 메뉴가 제공됨 - 태블릿 기능 설정 - 메시지 관리 - 광고 관리 - 홀 이벤트 관리 | J3: 태블릿 운영 관리 | K3: PASS
A4: =COUNTA($I$3:$I4) -> 2 | B4: 태블릿 운영 관리 | C4: 태블릿 기능 설정 | D4: - | E4: - | F4: 제공 정보 | G4: - | H4: 1. [태블릿 기능 설정] 메뉴 진입 2. 제공 정보 확인 | I4: 1. 태블릿 기능 설정 메뉴 제공됨(클라우드 UI) - 타이틀 : 태블릿 기능 설정 - 안내 문구 영역 - 경기 진행 설정 영역 - 카트도로 이탈 메시지 영역 - 긴급호출 연락처 영역 - 고객 확인서 영역 - 중대재해 확인서 영역 - 추가 확인서 영역 - 태블릿 설정 영역 | J4: 태블릿 기능 설정 | K4: PASS
A5: =COUNTA($I$3:$I5) -> 3 | B5: 태블릿 운영 관리 | C5: 태블릿 기능 설정 | D5: - | E5: - | F5: 안내 문구 | G5: - | H5: 1. 태블릿 기능 설정 안내 문구 확인 | I5: 1. 안내 문구 제공됨 - 문구 : 태블릿에 사용 가능한 기능들을 설정할 수 있습니다. \n 고객 확인서, 중대재해 확인서 및 카트 도로 이탈 메시지의 내용을 설정할 수 있으며, 긴급 호출 시 태블릿에 전송되는 연락처를 입력할 수 있습니다. | J5: 태블릿 기능 설정 | K5: PASS
A6: =COUNTA($I$3:$I6) -> 4 | B6: 태블릿 운영 관리 | C6: 태블릿 기능 설정 | D6: 경기 진행 설정 영역 | E6: - | F6: 제공 정보 | G6: - | H6: 1. 경기 진행 설정 영역 확인 | I6: 1. 경기 진행 설정 영역 제공됨 - 알림 문구 영역 - 전체 기능수 / 활성화 기능 / 비활성화 기능 - 기능 토글 13종 | J6: 태블릿 기능 설정 | K6: PASS | L6: QA-14845 | M6: 관제 지연카트 모니터링 기능이 다운로드로 제공되는 현상
A7: =COUNTA($I$3:$I7) -> 5 | B7: 태블릿 운영 관리 | C7: 태블릿 기능 설정 | E7: - | F7: 안내 문구 | G7: - | H7: 1. 안내 문구 확인 | I7: 1. 안내 문구 제공됨 - 태블릿에서 사용할 주요 기능의 노출 여부와 동작 방식을 설정합니다. | J7: 태블릿 기능 설정 | K7: PASS
A8: =COUNTA($I$3:$I8) -> 6 | B8: 태블릿 운영 관리 | C8: 태블릿 기능 설정 | E8: - | F8: 전체 기능 수 | G8: - | H8: 1. 전체 기능 수 영역 확인 | I8: 1. 전체 기능 수 제공됨(고정값) - 13 | J8: 태블릿 기능 설정 | K8: PASS
A9: =COUNTA($I$3:$I9) -> 7 | B9: 태블릿 운영 관리 | C9: 태블릿 기능 설정 | E9: - | F9: 활성화 기능 | G9: - | H9: 1. 활성화 기능 영역 확인 | I9: 1. 아래 기능이 활성화된 수 제공됨 - n | J9: 태블릿 기능 설정 | K9: PASS
A10: =COUNTA($I$3:$I10) -> 8 | B10: 태블릿 운영 관리 | C10: 태블릿 기능 설정 | E10: - | F10: 비활성화 기능 | G10: - | H10: 1. 비활성화 기능 영역 확인 | I10: 1. 아래 기능이 비활성화된 수 제공됨 - n | J10: 태블릿 기능 설정 | K10: PASS
A11: =COUNTA($I$3:$I11) -> 9 | B11: 태블릿 운영 관리 | C11: 태블릿 기능 설정 | E11: - | F11: 기능 토글 | G11: - | H11: 1. 기능 토글 영역 확인 | I11: 1. 13종 기능 토글 영역이 제공됨 - 컬럼 : 기능명 / 상세 설명 / 설정 | J11: 태블릿 기능 설정 | K11: PASS
A12: =COUNTA($I$3:$I12) -> 10 | B12: 태블릿 운영 관리 | C12: 태블릿 기능 설정 | E12: - | F12: 카트도로 이탈 방지 모드 | G12: - | H12: 1. 카트도로 이탈 방지 모드 영역 확인 | I12: 1. 카트도로 이탈 방지 모드 영역 제공됨 - 기능명 : 카트도로 이탈 방지 모드[툴팁] - 상세 설명 : 카트도로 이탈 시 태블릿에 경고창을 표시합니다. [셀프모드 전용] - 설정 : ON/OFF 토글 | J12: 태블릿 기능 설정 | K12: PASS | L12: QA-14845 | M12: 문구 오류
A13: =COUNTA($I$3:$I13) -> 11 | B13: 태블릿 운영 관리 | C13: 태블릿 기능 설정 | E13: - | G13: - | H13: 1. (i) 툴팁 버튼 선택 | I13: 1. 팝업 형태로 미리보기 화면 제공됨 - 타이틀 : 카트도로 이탈 방지 모드 - 문구 : 셀프모드에서 카트가 카트도로를 이탈했을때 태블릿에 경고팝업 송출 - [X] 버튼 - 미리보기 화면 - [닫기] 버튼 | J13: 태블릿 기능 설정 | K13: PASS | M13: 기획 변경
A14: =COUNTA($I$3:$I14) -> 12 | B14: 태블릿 운영 관리 | C14: 태블릿 기능 설정 | E14: - | G14: - | H14: 1. (i) 툴팁 버튼 선택 2. [X] 버튼 선택 | I14: 1. 팝업 닫힘 | J14: 태블릿 기능 설정 | K14: PASS
A15: =COUNTA($I$3:$I15) -> 13 | B15: 태블릿 운영 관리 | C15: 태블릿 기능 설정 | E15: - | G15: - | H15: 1. (i) 툴팁 버튼 선택 2. [닫기] 버튼 선택 | I15: 1. 팝업 닫힘 | J15: 태블릿 기능 설정 | K15: N/A | M15: 기획 변경
A16: =COUNTA($I$3:$I16) -> 14 | B16: 태블릿 운영 관리 | C16: 태블릿 기능 설정 | E16: - | G16: - | H16: 1. 토글 설정(ON or OFF) | I16: 1. 확인 팝업 제공됨 - 문구 : 설정을 변경하겠습니까? - [확인] / [취소] 버튼 | J16: 태블릿 기능 설정 | K16: PASS | L16: QA-14838 | M16: 확인 팝업 비제공
A17: =COUNTA($I$3:$I17) -> 15 | B17: 태블릿 운영 관리 | C17: 태블릿 기능 설정 | E17: - | G17: - | H17: 1. 토글 설정(ON or OFF) 2. [취소] 버튼 선택 | I17: 1. 토글 설정 취소됨 | J17: 태블릿 기능 설정 | K17: PASS
A18: =COUNTA($I$3:$I18) -> 16 | B18: 태블릿 운영 관리 | C18: 태블릿 기능 설정 | H18: 1. 토글 ON 설정 2. [확인] 버튼 선택 | I18: 1. 토글 설정 완료됨 * 카트도로 이탈 시 태블릿에 경고창 노출 | J18: 태블릿 기능 설정 | K18: PASS | L18: QA-14836 | M18: 서버에러 *카트 연동은 범위 제외
A19: =COUNTA($I$3:$I19) -> 17 | B19: 태블릿 운영 관리 | C19: 태블릿 기능 설정 | E19: - | G19: - | H19: 1. 토글 OFF 설정 2. [확인] 버튼 선택 | I19: 1. 토글 설정 완료됨 * 카트도로 이탈 시 태블릿에 경고창 비노출 | J19: 태블릿 기능 설정 | K19: PASS | L19: QA-14836 | M19: 서버에러 *카트 연동은 범위 제외
A20: =COUNTA($I$3:$I20) -> 18 | B20: 태블릿 운영 관리 | C20: 태블릿 기능 설정 | D20: 경기 진행 설정 영역 | E20: - | F20: 고객확인서 팝업 | G20: - | H20: 1. 고객확인서 팝업 영역 확인 | I20: 1. 고객확인서 팝업 영역 제공됨 - 기능명 : 고객확인서[툴팁] - 상세 설명 : 라운드 시작 시 고객확인서를 팝업으로 표시합니다. - 설정 : ON/OFF 토글 | J20: 태블릿 기능 설정 | K20: PASS | L20: QA-14845 | M20: 문구 오류
A21: =COUNTA($I$3:$I21) -> 19 | B21: 태블릿 운영 관리 | C21: 태블릿 기능 설정 | E21: - | G21: - | H21: 1. (i) 툴팁 버튼 선택 | I21: 1. 팝업 형태로 미리보기 화면 제공됨 - 타이틀 : 고객확인서 팝업 - 문구 : 라운드 시작 시 고객확인서를 팝업으로 띄우는 기능 - [X] 버튼 - 미리보기 화면 - [닫기] 버튼 | J21: 태블릿 기능 설정 | K21: PASS
A22: =COUNTA($I$3:$I22) -> 20 | B22: 태블릿 운영 관리 | C22: 태블릿 기능 설정 | E22: - | G22: - | H22: 1. (i) 툴팁 버튼 선택 2. [X] 버튼 선택 | I22: 1. 팝업 닫힘 | J22: 태블릿 기능 설정 | K22: PASS
A23: =COUNTA($I$3:$I23) -> 21 | B23: 태블릿 운영 관리 | C23: 태블릿 기능 설정 | E23: - | G23: - | H23: 1. (i) 툴팁 버튼 선택 2. [닫기] 버튼 선택 | I23: 1. 팝업 닫힘 | J23: 태블릿 기능 설정 | K23: N/A | M23: 기획 변경
A24: =COUNTA($I$3:$I24) -> 22 | B24: 태블릿 운영 관리 | C24: 태블릿 기능 설정 | H24: 1. 토글 설정(ON or OFF) | I24: 1. 확인 팝업 제공됨 - 문구 : 설정을 변경하겠습니까? - [확인] / [취소] 버튼 | J24: 태블릿 기능 설정 | K24: PASS | L24: QA-14838 | M24: 확인 팝업 비제공
A25: =COUNTA($I$3:$I25) -> 23 | B25: 태블릿 운영 관리 | C25: 태블릿 기능 설정 | E25: - | G25: - | H25: 1. 토글 설정(ON or OFF) 2. [취소] 버튼 선택 | I25: 1. 토글 설정 취소됨 | J25: 태블릿 기능 설정 | K25: PASS
A26: =COUNTA($I$3:$I26) -> 24 | B26: 태블릿 운영 관리 | C26: 태블릿 기능 설정 | E26: - | G26: - | H26: 1. 토글 ON 설정 2. [확인] 버튼 선택 | I26: 1. 토글 설정 완료됨 * 태블릿에 고객확인서 제공 | J26: 태블릿 기능 설정 | K26: PASS | L26: QA-14836 | M26: 서버에러
A27: =COUNTA($I$3:$I27) -> 25 | B27: 태블릿 운영 관리 | C27: 태블릿 기능 설정 | E27: - | G27: - | H27: 1. 토글 OFF 설정 2. [확인] 버튼 선택 | I27: 1. 토글 설정 완료됨 * 태블릿에 고객확인서 비제공 | J27: 태블릿 기능 설정 | K27: PASS | L27: QA-14836 | M27: 서버에러
A28: =COUNTA($I$3:$I28) -> 26 | B28: 태블릿 운영 관리 | C28: 태블릿 기능 설정 | D28: 경기 진행 설정 영역 | E28: - | F28: 중대재해 확인서 | G28: - | H28: 1. 중대재해 확인서 영역 확인 | I28: 1. 중대재해 확인서 영역 제공됨 - 기능명 : 중대재해 확인서[툴팁] - 상세 설명 : 중대재해 고객확인서 기능을 사용합니다. - 설정 : ON/OFF 토글 | J28: 태블릿 기능 설정 | K28: PASS
A29: =COUNTA($I$3:$I29) -> 27 | B29: 태블릿 운영 관리 | C29: 태블릿 기능 설정 | E29: - | G29: - | H29: 1. (i) 툴팁 버튼 선택 | I29: 1. 팝업 형태로 미리보기 화면 제공됨 - 타이틀 : 중대재해 확인서 - 문구 : 중대재해 확인서를 오픈하는 기능 - [X] 버튼 - 미리보기 화면 - [닫기] 버튼 | J29: 태블릿 기능 설정 | K29: PASS
A30: =COUNTA($I$3:$I30) -> 28 | B30: 태블릿 운영 관리 | C30: 태블릿 기능 설정 | E30: - | G30: - | H30: 1. (i) 툴팁 버튼 선택 2. [X] 버튼 선택 | I30: 1. 팝업 닫힘 | J30: 태블릿 기능 설정 | K30: PASS
A31: =COUNTA($I$3:$I31) -> 29 | B31: 태블릿 운영 관리 | C31: 태블릿 기능 설정 | E31: - | G31: - | H31: 1. (i) 툴팁 버튼 선택 2. [닫기] 버튼 선택 | I31: 1. 팝업 닫힘 | J31: 태블릿 기능 설정 | K31: N/A | M31: 기획 변경
A32: =COUNTA($I$3:$I32) -> 30 | B32: 태블릿 운영 관리 | C32: 태블릿 기능 설정 | E32: - | G32: - | H32: 1. 토글 설정(ON or OFF) | I32: 1. 확인 팝업 제공됨 - 문구 : 설정을 변경하겠습니까? - [확인] / [취소] 버튼 | J32: 태블릿 기능 설정 | K32: PASS | L32: QA-14838 | M32: 확인 팝업 비제공
A33: =COUNTA($I$3:$I33) -> 31 | B33: 태블릿 운영 관리 | C33: 태블릿 기능 설정 | H33: 1. 토글 설정(ON or OFF) 2. [취소] 버튼 선택 | I33: 1. 토글 설정 취소됨 | J33: 태블릿 기능 설정 | K33: PASS
A34: =COUNTA($I$3:$I34) -> 32 | B34: 태블릿 운영 관리 | C34: 태블릿 기능 설정 | E34: - | G34: - | H34: 1. 토글 ON 설정 2. [확인] 버튼 선택 | I34: 1. 토글 설정 완료됨 * 태블릿에 중대재해 확인서 제공 | J34: 태블릿 기능 설정 | K34: PASS
A35: =COUNTA($I$3:$I35) -> 33 | B35: 태블릿 운영 관리 | C35: 태블릿 기능 설정 | E35: - | G35: - | H35: 1. 토글 OFF 설정 2. [확인] 버튼 선택 | I35: 1. 토글 설정 완료됨 * 태블릿에 중대재해 확인서 비제공 | J35: 태블릿 기능 설정 | K35: PASS
A36: =COUNTA($I$3:$I36) -> 34 | B36: 태블릿 운영 관리 | C36: 태블릿 기능 설정 | E36: - | G36: 1. 설정 : OFF 상태 | H36: 1. 중대재해 확인서 하위 메뉴 확인 | I36: 1. 중대재해 확인서 OFF 시 비제공됨 | J36: 태블릿 기능 설정 | K36: PASS
A37: =COUNTA($I$3:$I37) -> 35 | B37: 태블릿 운영 관리 | C37: 태블릿 기능 설정 | E37: - | G37: 1. 설정 : ON 상태 | H37: 1. 중대재해 확인서 하위 메뉴 확인 | I37: 1. 중대재해 확인서 ON 시 제공됨 - 상세 설명 : 중대재해 고객확인서 저장을 필수로 합니다. - [예] / [아니오] 버튼 | J37: 태블릿 기능 설정 | K37: PASS
A38: =COUNTA($I$3:$I38) -> 36 | B38: 태블릿 운영 관리 | C38: 태블릿 기능 설정 | E38: - | H38: 1. [예] / [아니오] 버튼 확인 | I38: 1. 예 / 아니오 설정 가능함 | J38: 태블릿 기능 설정 | K38: PASS
A39: =COUNTA($I$3:$I39) -> 37 | B39: 태블릿 운영 관리 | C39: 태블릿 기능 설정 | D39: 경기 진행 설정 영역 | E39: - | F39: 추가 확인서 | G39: - | H39: 1. 추가 확인서 영역 확인 | I39: 1. 추가 확인서 영역 제공됨 - 기능명 : 추가 확인서[툴팁] - 상세 설명 : 추가 확인서 기능을 사용합니다. - 설정 : ON/OFF 토글 | J39: 태블릿 기능 설정 | K39: PASS
A40: =COUNTA($I$3:$I40) -> 38 | B40: 태블릿 운영 관리 | C40: 태블릿 기능 설정 | E40: - | G40: - | H40: 1. (i) 툴팁 버튼 선택 | I40: 1. 팝업 형태로 미리보기 화면 제공됨 - 타이틀 : 추가 확인서 - 문구 : 추가 확인서 기능을 사용하는 경우, 확인 항목을 커스터마이징하여 관리할 수 있습니다. - [X] 버튼 - 미리보기 화면 - [닫기] 버튼 | J40: 태블릿 기능 설정 | K40: PASS
...

Sheet 홀맵 관리
A1: No. | C1: 화면 | F1: 기능 | G1: 사전 조건 | H1: 절차 | I1: 예상결과 | J1: 기획서 | K1: QA 확인 결과 | L1: JIRA | M1: 비고 | N1: 담당자
B2: 0 dapth | C2: 1 depth | D2: 2 depth | E2: 3 depth
A3: =COUNTA($I$3:$I3) -> 1 | B3: 홀맵 관리 | C3: 홀맵 구역 관리 | F3: 제공 정보 | H3: 1. [홀맵 구역 관리] 메뉴 진입 | I3: 1. 홀맵 구역 관리 진입됨 2. 아래 정보 노출됨 - 메뉴 설명 영역 - 검색 영역 - 홀맵구역 테이블 영역 | J3: 홀맵구역관리 | K3: FAIL | L3: QA-14818 | M3: 홀맵 구역 관리로 노출됨 (기획서 SBN : 홀맵 구역 설정)
A4: =COUNTA($I$3:$I4) -> 2 | D4: 메뉴 설명 영역 | F4: 제공 정보 | H4: 1. 메뉴 설명 영역 확인 | I4: 1. 아래 정보 노출됨 - Title : 홀맵 구역 관리 - 문구 : 페어웨이 진입 알림 설정과 코스별 허용 상태를 관리하고, 홀맵 구역 데이터를 조회할 수 있습니다. - [현재버전 ##▲#] | J4: 홀맵구역관리 | K4: PASS
A5: =COUNTA($I$3:$I5) -> 3 | F5: 랜딩 | G5: 1. 업데이트 가능한 버전이 있는 경우 | H5: 1. [현재버전 ##▲#] 버튼 선택 | I5: 1. 알림 팝업 노출됨 - Title : 알림 - 문구 : 버전을 올리시겠습니까? - [취소], [확인] 버튼 | J5: - | K5: PASS | M5: 기획서 없음
A6: =COUNTA($I$3:$I6) -> 4 | F6: 랜딩 | G6: 1. 업데이트 가능한 버전이 있는 경우 2. 버전 업데이트 알림 팝업 노출된 상태 | H6: 1. [취소] 버튼 선택 | I6: 1. 팝업 닫히며, 이전 화면으로 전환됨 | J6: - | K6: PASS | M6: 기획서 없음
A7: =COUNTA($I$3:$I7) -> 5 | F7: 랜딩 | G7: 1. 업데이트 가능한 버전이 있는 경우 2. 버전 업데이트 알림 팝업 노출된 상태 | H7: 1. [확인] 버튼 선택 | I7: 1. 토스트 팝업 노출됨 - 문구 : 버전이 업데이트 되었습니다. | J7: - | K7: PASS | M7: 기획서 없음
A8: =COUNTA($I$3:$I8) -> 6 | D8: 검색영역 | F8: 제공 정보 | H8: 1. 검색 영역 확인 | I8: 1. 아래 정보 노출됨 - [전체코스v] 필터 - [전체홀v] 필터 - [전체구역v] 필터 - [초기화] 버튼 [적용] 버튼 | J8: 홀맵구역관리 | K8: PASS
A9: =COUNTA($I$3:$I9) -> 7 | F9: 코스 필터 | H9: 1. 코스필터 (코스 전체v) 선택 2. 코스 전체 선택 3. [적용] 버튼 선택 | I9: 1. 코스 리스트 노출됨 2. 코스 전체 설정됨 3. 모든코스의 홀맵구역 정보 노출됨 | J9: 홀맵구역관리 | K9: PASS
A10: =COUNTA($I$3:$I10) -> 8 | F10: 코스 필터 | H10: 1. 코스필터 (코스 전체v) 선택 2. 임의의 코스 선택 3. [적용] 버튼 선택 | I10: 1. 코스 리스트 노출됨 2. 선택한 코스 설정됨 3. 설정한 코스의 홀맵구역 정보 노출됨 | J10: 홀맵구역관리 | K10: PASS
A11: =COUNTA($I$3:$I11) -> 9 | F11: 홀 필터 | H11: 1. 홀필터 (홀 전체v) 선택 2. 홀 전체 선택 3. [적용] 버튼 선택 | I11: 1. 홀 리스트 노출됨 2. 홀 전체 설정됨 3. 모든홀의 홀맵구역 정보 노출됨 | J11: 홀맵구역관리 | K11: PASS
A12: =COUNTA($I$3:$I12) -> 10 | F12: 홀 필터 | G12: 1. 임의의 코스 선택된 상태 | H12: 1. 홀필터 (홀 전체v) 선택 2. 임의의 홀 선택 3. [적용] 버튼 선택 | I12: 1. 홀 리스트 노출됨 2. 선택한 홀 설정됨 3. 설정한 홀의 홀맵구역 정보 노출됨 | J12: 홀맵구역관리 | K12: PASS
A13: =COUNTA($I$3:$I13) -> 11 | F13: 구역 필터 | H13: 1. 구역필터 (구역 전체v) 선택 2. 구역 전체 선택 3. [적용] 버튼 선택 | I13: 1. 구역 리스트 노출됨 2. 구역 전체 설정됨 3. 모든구역의 구역맵구역 정보 노출됨 | J13: 홀맵구역관리 | K13: PASS
A14: =COUNTA($I$3:$I14) -> 12 | F14: 구역 필터 | H14: 1. 구역필터 (구역 전체v) 선택 2. 임의의 구역 선택 3. [적용] 버튼 선택 | I14: 1. 구역 리스트 노출됨 2. 선택한 구역 설정됨 3. 설정한 구역의 구역맵구역 정보 노출됨 | J14: 홀맵구역관리 | K14: PASS | L14: QA-14819 | M14: 거리표시, 특정 위치 알림, 다음 홀 방향 필터 시, 모든 항목 노출됨
A15: =COUNTA($I$3:$I15) -> 13 | F15: 초기화 버튼 | H15: 1. 코스, 홀, 구역 설정 2. [초기화] 버튼 선택 | I15: 1. 코스, 홀, 구역 필터 초기화됨 - 전체코스, 전체홀, 전체구역 | J15: 홀맵구역관리 | K15: PASS
A16: =COUNTA($I$3:$I16) -> 14 | F16: 적용 버튼 | H16: 1. 코스, 홀, 구역 설정 2. [적용] 버튼 선택 | I16: 1. 코스, 홀, 구역 설정됨 2. 설정한 코스, 홀, 구역의 정보 필터되어 노출됨 | J16: 홀맵구역관리 | K16: PASS
A17: =COUNTA($I$3:$I17) -> 15 | D17: 홀맵구역 테이블 영역 | F17: 제공 정보 | H17: 1. 홀맵구역 테이블 확인 | I17: 1. 아래 정보 노출됨 - No. / 코스 / 홀 / PAR / 야디지 / 위험구역 / OB구역 / 패널티구역 / 뒷카트알림 / 거리표시 / 특정 위치 알림 / 다음 홀 방향 / 관리 / 작업자 / 아이피 / 등록날짜 | J17: 홀맵구역관리 | K17: PASS
A18: =COUNTA($I$3:$I18) -> 16 | F18: 제공 정보 | H18: 1. 각 구역별 정보 확인 | I18: 1. 각 구역별 정보 노출됨 - No. / 코스 / 홀 / PAR / 야디지 / 위험구역 / OB구역 / 패널티구역 / 뒷카트알림 / 거리표시 / 특정 위치 알림 / 다음 홀 방향 / 관리 / 작업자 / 아이피 / 등록날짜 | J18: 홀맵구역관리 | K18: PASS
A19: =COUNTA($I$3:$I19) -> 17 | F19: 제공 정보 | H19: 1. 코스, 홀, 구역 변경 2. [적용] 버튼 선택 3. 홀맵구역 테이블 확인 | I19: 1. 코스, 홀, 구역 선택됨 2. 변경사항 적용됨 3. 변경된 코스, 홀, 구역의 홀맵구역 테이블 정보 노출됨 | J19: 홀맵구역관리 | K19: PASS
A20: =COUNTA($I$3:$I20) -> 18 | E20: 구역관리 레이어 팝업 | F20: 랜딩 | H20: 1. [구역관리] 버튼 선택 | I20: 1. 구역 관리 레이어 팝업 노출됨 | J20: 홀맵구역관리 | K20: PASS
A21: =COUNTA($I$3:$I21) -> 19 | F21: 제공 정보 | G21: 1. 구역관리 레이어 팝업 노출된 상태 | H21: 1. 구역 관리 레이어 팝업 확인 | I21: 1. 아래 정보 노출됨 - Title : 구역관리 - 코스, 홀, 파 - 등록 일시 - [X] 버튼 | J21: 홀맵구역관리 | K21: PASS
A22: =COUNTA($I$3:$I22) -> 20 | F22: 제공 정보 | H22: 1. 지도 영역 확인 | I22: 1. 아래 정보 노출됨 - Tool tip : ⓘ지도 위에 직접 표시하는 작업 공간 [X] 버튼 | J22: 홀맵구역관리 | K22: PASS
A23: =COUNTA($I$3:$I23) -> 21 | F23: 랜딩 | H23: 1. 툴팁 - [X] 버튼 선택 | I23: 1. 툴팁 닫힘 | J23: 홀맵구역관리 | K23: PASS
A24: =COUNTA($I$3:$I24) -> 22 | F24: 랜딩 | H24: 1. 구역관리 레이어 팝업 재진입 | I24: 1. 툴팁 노출됨 | J24: 홀맵구역관리 | K24: PASS
A25: =COUNTA($I$3:$I25) -> 23 | F25: 랜딩 | G25: 1. 구역관리 레이어 팝업 노출된 상태 | H25: 1. [X] 버튼 선택 | I25: 1. 팝업 닫히며, 이전 화면으로 전환됨 | J25: 홀맵구역관리 | K25: PASS
A26: =COUNTA($I$3:$I26) -> 24 | E26: 구역관리 레이어 팝업 > 지도 옵션 | F26: 제공 정보 | G26: 1. 구역관리 레이어 팝업 노출된 상태 | H26: 1. 지도 옵션 영역 확인 | I26: 1. 아래 정보 노출됨 - Title : 지도 옵션 - 지도/위성/홀맵 /정보 radio Btn | J26: 홀맵구역관리 | K26: FAIL | L26: QA-14818 | M26: "지도유형"으로 노출됨
A27: =COUNTA($I$3:$I27) -> 25 | F27: 지도 | G27: 1. 구역관리 레이어 팝업 노출된 상태 | H27: 1. [지도] 라디오버튼 선택 2. 지도 영역 확인 3. [+] 버튼 [-] 버튼 | I27: 1. 지도 라디오버튼 활성화됨 2. 지도 화면 노출됨 3. 지도 화면 확대/축소됨 | J27: 홀맵구역관리 | K27: PASS | L27: QA-14826 | M27: 축소 시 줌 레벨이 올라감.
A28: =COUNTA($I$3:$I28) -> 26 | F28: 위성 | G28: 1. 구역관리 레이어 팝업 노출된 상태 | H28: 1. [위성] 라디오버튼 선택 2. 지도 영역 확인 3. [+] 버튼 [-] 버튼 | I28: 1. 위성 라디오버튼 활성화됨 2. 위성 화면 노출됨 3. 위성 화면 확대/축소됨 | J28: 홀맵구역관리 | K28: PASS | L28: QA-14826 | M28: 축소 시 줌 레벨이 올라감.
A29: =COUNTA($I$3:$I29) -> 27 | F29: 홀맵 | G29: 1. 구역관리 레이어 팝업 노출된 상태 | H29: 1. [홀맵] 라디오버튼 선택 2. 지도 영역 확인 | I29: 1. 홀맵 라디오버튼 활성화됨 2. 홀맵 화면 노출되며, 홀맵 주변 지형들도 노출됨 | J29: 홀맵구역관리 | K29: PASS
A30: =COUNTA($I$3:$I30) -> 28 | F30: 홀맵 | G30: 1. 구역관리 레이어 팝업 노출된 상태 2. 지도유형 - [홀맵] 라디오 버튼 선택된 상태 | H30: 1. [+], [-] 버튼 확인 | I30: 1. 비활성화 되어있음 | J30: 홀맵구역관리 | K30: PASS | L30: QA-14830 | M30: 지도유형 - 홀맵 선택 시, [+], [-] 버튼 활성화 되어있음.
A31: =COUNTA($I$3:$I31) -> 29 | F31: 정보 | G31: 1. 구역관리 레이어 팝업 노출된 상태 | H31: 1. [정보] 라디오버튼 선택 2. 지도 영역 확인 3. [+] 버튼 [-] 버튼 | I31: 1. 정보 라디오버튼 활성화됨 2. 정보 화면 노출됨 3. 정보 화면 확대/축소됨 | J31: 홀맵구역관리 | K31: PASS
A32: =COUNTA($I$3:$I32) -> 30 | E32: 구역관리 레이어 팝업 > 설정 탭 | F32: 위험구역 설정 | H32: 1. [위험구역 설정] 선택 | I32: 1. 하단에 기능 안내 팝업 노출됨 - Title : 위험구역 추가 [X] 버튼 - 문구 : 지도 위 꼭짓점을 클릭하여 위험구역 영역을 지정하세요. | J32: - | K32: PASS | M32: 기획서 없음
A33: =COUNTA($I$3:$I33) -> 31 | F33: 위험구역 설정 | G33: 1. 위험구역 설정 안내 팝업 노출된 상태 | H33: 1. [X] 버튼 선택 | I33: 1. 팝업 닫히며 이전 화면으로 전환됨 | K33: PASS
A34: =COUNTA($I$3:$I34) -> 32 | F34: 위험구역 설정 | H34: 1. 지도 화면 클릭 2. 마우스 이용하여 구역 그리기 | I34: 1. 우측 지도 영역에서 구역을 그릴 수 있도록 마우스 동작 활성화됨 2. 영역 표시되며, 좌표 선택중 팝업 노출됨 - Title : 좌표 선택중 - 문구 : 꼭짓점을 계속 클릭하고, 완료 후 "추가" 버튼을 누르세요. (위험구역)? - 전체면적 : 1296.63㎡ (13956.75 ft²) - 총 거리 : 165.11m (541.71 ft) - [취소] 버튼 [추가] 버튼 | J34: 홀맵구역관리 | K34: PASS
A35: =COUNTA($I$3:$I35) -> 33 | F35: 위험구역 설정 | G35: 1. 위험구역 추가 팝업 노출된 상태 | H35: 1. [취소] 버튼 선택 | I35: 1. 팝업 닫히며 이전 화면으로 전환됨 | J35: 홀맵구역관리 | K35: PASS
A36: =COUNTA($I$3:$I36) -> 34 | F36: 위험구역 설정 | G36: 1. 위험구역 추가 팝업 노출된 상태 | H36: 1. [등록] 버튼 선택 | I36: 1. 설정한 영역이 위험 구역으로 등록됨 | J36: 홀맵구역관리 | K36: PASS
A37: =COUNTA($I$3:$I37) -> 35 | F37: 플레이 영역 설정 > OB 설정 | H37: 1. 플레이구역 설정 클릭 2. OB 설정 클릭 3. 마우스 이용하여 점을 찍어 선 그리기 | I37: 1. 플레이구역 설정 메뉴 펼쳐짐 2. 우측 지도 영역에서 점을 찍으며 선을 그릴수 있도록 마우스 동작 활성화됨 3. 처음에 OB 라고 표시되는 텍스트가 중앙에 표시되며, 구역 추가 여부를 묻는 팝업 노출됨 - Title : 좌표 선택중 - 문구 : 꼭짓점을 계속 클릭하고, 완료 후 "추가" 버튼을 누르세요. (OB구역) - 총 거리 : 120.66m (395.85 ft) - [취소] [---추가] 버튼 | J37: 홀맵구역관리 | K37: PASS | L37: QA-14835 | M37: 플레이 영역 설정의 경우, 컬러 원형 도형 미노출됨.
A38: =COUNTA($I$3:$I38) -> 36 | F38: 플레이 영역 설정 > OB 설정 | G38: 1. 위험구역 추가 팝업 노출된 상태 | H38: 1. [취소] 버튼 선택 | I38: 1. 팝업 닫히며 이전 화면으로 전환됨 | J38: 홀맵구역관리 | K38: PASS
A39: =COUNTA($I$3:$I39) -> 37 | F39: 플레이 영역 설정 > OB 설정 | G39: 1. 위험구역 추가 팝업 노출된 상태 | H39: 1. [추가] 버튼 선택 | I39: 1. 설정한 영역이 위험 구역으로 등록됨 | J39: 홀맵구역관리 | K39: PASS
A40: =COUNTA($I$3:$I40) -> 38 | F40: 플레이 영역 설정 > OB 설정 | G40: 1. OB 선 그려져있는 상태 | H40: 1. 마우스 드래그하여 텍스트 위치 변경 | I40: 1. 텍스트 위치 변경됨 | J40: 홀맵구역관리 | K40: PASS
...

Sheet 코스 운영 관리
A1: No. | C1: 화면 | F1: 기능 | G1: 사전 조건 | H1: 절차 | I1: 예상결과 | J1: 기획서 | K1: QA 확인 결과 | L1: JIRA | M1: 비고 | N1: 담당자
